ERROR 2019-01-24 17:40:34,616 log Internal Server Error: /api/ticket/create/
Traceback (most recent call last):
  File "/usr/local/python3/lib/python3.6/site-packages/django/core/handlers/exception.py", line 34, in inner
    response = get_response(request)
  File "/usr/local/python3/lib/python3.6/site-packages/django/core/handlers/base.py", line 126, in _get_response
    response = self.process_exception_by_middleware(e, request)
  File "/usr/local/python3/lib/python3.6/site-packages/django/core/handlers/base.py", line 124, in _get_response
    response = wrapped_callback(request, *callback_args, **callback_kwargs)
  File "/usr/local/python3/lib/python3.6/site-packages/django/views/generic/base.py", line 68, in view
    return self.dispatch(request, *args, **kwargs)
  File "/usr/local/python3/lib/python3.6/site-packages/django/views/generic/base.py", line 88, in dispatch
    return handler(request, *args, **kwargs)
  File "./ticket/ticket_view/ticket.py", line 92, in post
    sender_email_ticket(ticket)
  File "./ticket/ticket_view/send_email.py", line 13, in sender_email_ticket
    senderuser, fail_silently=False)
  File "/usr/local/python3/lib/python3.6/site-packages/django/core/mail/__init__.py", line 60, in send_mail
    return mail.send()
  File "/usr/local/python3/lib/python3.6/site-packages/django/core/mail/message.py", line 291, in send
    return self.get_connection(fail_silently).send_messages([self])
  File "/usr/local/python3/lib/python3.6/site-packages/django/core/mail/backends/smtp.py", line 110, in send_messages
    sent = self._send(message)
  File "/usr/local/python3/lib/python3.6/site-packages/django/core/mail/backends/smtp.py", line 126, in _send
    self.connection.sendmail(from_email, recipients, message.as_bytes(linesep='\r\n'))
  File "/usr/local/python3/lib/python3.6/smtplib.py", line 888, in sendmail
    raise SMTPDataError(code, resp)
smtplib.SMTPDataError: (554, b'DT:SPM 163 smtp14,EsCowABXoN8SiElcRiPGCw--.30064S2 1548322834,please see http://mail.163.com/help/help_spam_16.htm?ip=219.141.250.88&hostid=smtp14&time=1548322834')
WARNING 2019-01-25 09:03:04,029 log Not Found: /favicon.ico
WARNING 2019-01-25 09:03:07,754 log Not Found: /favicon.ico
WARNING 2019-01-25 09:03:11,908 log Not Found: /favicon.ico
ERROR 2019-01-25 09:05:15,882 log Internal Server Error: /api/ticket/server/detail/
Traceback (most recent call last):
  File "/usr/local/lib/python3.6/site-packages/django/core/handlers/exception.py", line 34, in inner
    response = get_response(request)
  File "/usr/local/lib/python3.6/site-packages/django/core/handlers/base.py", line 126, in _get_response
    response = self.process_exception_by_middleware(e, request)
  File "/usr/local/lib/python3.6/site-packages/django/core/handlers/base.py", line 124, in _get_response
    response = wrapped_callback(request, *callback_args, **callback_kwargs)
  File "/usr/local/lib/python3.6/site-packages/django/views/generic/base.py", line 68, in view
    return self.dispatch(request, *args, **kwargs)
  File "/usr/local/lib/python3.6/site-packages/django/views/generic/base.py", line 88, in dispatch
    return handler(request, *args, **kwargs)
  File "/Users/zhang/Documents/Python/PESCM/ticket/ticket_view/ticket.py", line 367, in post
    ticket.save()
  File "/usr/local/lib/python3.6/site-packages/django/db/models/base.py", line 718, in save
    force_update=force_update, update_fields=update_fields)
  File "/usr/local/lib/python3.6/site-packages/django/db/models/base.py", line 748, in save_base
    updated = self._save_table(raw, cls, force_insert, force_update, using, update_fields)
  File "/usr/local/lib/python3.6/site-packages/django/db/models/base.py", line 812, in _save_table
    forced_update)
  File "/usr/local/lib/python3.6/site-packages/django/db/models/base.py", line 861, in _do_update
    return filtered._update(values) > 0
  File "/usr/local/lib/python3.6/site-packages/django/db/models/query.py", line 712, in _update
    return query.get_compiler(self.db).execute_sql(CURSOR)
  File "/usr/local/lib/python3.6/site-packages/django/db/models/sql/compiler.py", line 1383, in execute_sql
    cursor = super().execute_sql(result_type)
  File "/usr/local/lib/python3.6/site-packages/django/db/models/sql/compiler.py", line 1052, in execute_sql
    sql, params = self.as_sql()
  File "/usr/local/lib/python3.6/site-packages/django/db/models/sql/compiler.py", line 1349, in as_sql
    val = field.get_db_prep_save(val, connection=self.connection)
  File "/usr/local/lib/python3.6/site-packages/django/db/models/fields/__init__.py", line 790, in get_db_prep_save
    return self.get_db_prep_value(value, connection=connection, prepared=False)
  File "/usr/local/lib/python3.6/site-packages/django/db/models/fields/__init__.py", line 1273, in get_db_prep_value
    value = self.get_prep_value(value)
  File "/usr/local/lib/python3.6/site-packages/django/db/models/fields/__init__.py", line 1268, in get_prep_value
    return self.to_python(value)
  File "/usr/local/lib/python3.6/site-packages/django/db/models/fields/__init__.py", line 1230, in to_python
    parsed = parse_date(value)
  File "/usr/local/lib/python3.6/site-packages/django/utils/dateparse.py", line 74, in parse_date
    match = date_re.match(value)
TypeError: expected string or bytes-like object
ERROR 2019-01-25 09:07:52,317 log Internal Server Error: /api/ticket/server/detail/
Traceback (most recent call last):
  File "/usr/local/lib/python3.6/site-packages/django/core/handlers/exception.py", line 34, in inner
    response = get_response(request)
  File "/usr/local/lib/python3.6/site-packages/django/core/handlers/base.py", line 126, in _get_response
    response = self.process_exception_by_middleware(e, request)
  File "/usr/local/lib/python3.6/site-packages/django/core/handlers/base.py", line 124, in _get_response
    response = wrapped_callback(request, *callback_args, **callback_kwargs)
  File "/usr/local/lib/python3.6/site-packages/django/views/generic/base.py", line 68, in view
    return self.dispatch(request, *args, **kwargs)
  File "/usr/local/lib/python3.6/site-packages/django/views/generic/base.py", line 88, in dispatch
    return handler(request, *args, **kwargs)
  File "/Users/zhang/Documents/Python/PESCM/ticket/ticket_view/ticket.py", line 367, in post
    ticket.save()
  File "/usr/local/lib/python3.6/site-packages/django/db/models/base.py", line 718, in save
    force_update=force_update, update_fields=update_fields)
  File "/usr/local/lib/python3.6/site-packages/django/db/models/base.py", line 748, in save_base
    updated = self._save_table(raw, cls, force_insert, force_update, using, update_fields)
  File "/usr/local/lib/python3.6/site-packages/django/db/models/base.py", line 812, in _save_table
    forced_update)
  File "/usr/local/lib/python3.6/site-packages/django/db/models/base.py", line 861, in _do_update
    return filtered._update(values) > 0
  File "/usr/local/lib/python3.6/site-packages/django/db/models/query.py", line 712, in _update
    return query.get_compiler(self.db).execute_sql(CURSOR)
  File "/usr/local/lib/python3.6/site-packages/django/db/models/sql/compiler.py", line 1383, in execute_sql
    cursor = super().execute_sql(result_type)
  File "/usr/local/lib/python3.6/site-packages/django/db/models/sql/compiler.py", line 1052, in execute_sql
    sql, params = self.as_sql()
  File "/usr/local/lib/python3.6/site-packages/django/db/models/sql/compiler.py", line 1349, in as_sql
    val = field.get_db_prep_save(val, connection=self.connection)
  File "/usr/local/lib/python3.6/site-packages/django/db/models/fields/__init__.py", line 790, in get_db_prep_save
    return self.get_db_prep_value(value, connection=connection, prepared=False)
  File "/usr/local/lib/python3.6/site-packages/django/db/models/fields/__init__.py", line 1273, in get_db_prep_value
    value = self.get_prep_value(value)
  File "/usr/local/lib/python3.6/site-packages/django/db/models/fields/__init__.py", line 1268, in get_prep_value
    return self.to_python(value)
  File "/usr/local/lib/python3.6/site-packages/django/db/models/fields/__init__.py", line 1230, in to_python
    parsed = parse_date(value)
  File "/usr/local/lib/python3.6/site-packages/django/utils/dateparse.py", line 74, in parse_date
    match = date_re.match(value)
TypeError: expected string or bytes-like object
WARNING 2019-01-25 09:32:13,814 log Not Found: /favicon.ico
WARNING 2019-01-25 09:32:17,316 log Not Found: /favicon.ico
WARNING 2019-01-25 09:52:41,775 log Not Found: /favicon.ico
WARNING 2019-01-25 10:18:16,348 log Not Found: /favicon.ico
<<<<<<< HEAD
WARNING 2019-01-25 14:30:59,148 log Not Found: /uploads/image/default.png
=======
WARNING 2019-01-29 12:23:40,736 log Not Found: /
ERROR 2019-01-29 12:23:56,425 log Internal Server Error: /api/ticket/send/
Traceback (most recent call last):
  File "/usr/local/lib/python3.6/site-packages/django/core/handlers/exception.py", line 34, in inner
    response = get_response(request)
  File "/usr/local/lib/python3.6/site-packages/django/core/handlers/base.py", line 126, in _get_response
    response = self.process_exception_by_middleware(e, request)
  File "/usr/local/lib/python3.6/site-packages/django/core/handlers/base.py", line 124, in _get_response
    response = wrapped_callback(request, *callback_args, **callback_kwargs)
TypeError: sender() takes 0 positional arguments but 1 was given
ERROR 2019-01-29 12:24:24,047 log Internal Server Error: /api/ticket/send/
Traceback (most recent call last):
  File "/usr/local/lib/python3.6/site-packages/django/core/handlers/exception.py", line 34, in inner
    response = get_response(request)
  File "/usr/local/lib/python3.6/site-packages/django/core/handlers/base.py", line 126, in _get_response
    response = self.process_exception_by_middleware(e, request)
  File "/usr/local/lib/python3.6/site-packages/django/core/handlers/base.py", line 124, in _get_response
    response = wrapped_callback(request, *callback_args, **callback_kwargs)
TypeError: sender() takes 0 positional arguments but 1 was given
ERROR 2019-01-29 12:24:27,369 log Internal Server Error: /api/ticket/send/
Traceback (most recent call last):
  File "/usr/local/lib/python3.6/site-packages/django/core/handlers/exception.py", line 34, in inner
    response = get_response(request)
  File "/usr/local/lib/python3.6/site-packages/django/core/handlers/base.py", line 126, in _get_response
    response = self.process_exception_by_middleware(e, request)
  File "/usr/local/lib/python3.6/site-packages/django/core/handlers/base.py", line 124, in _get_response
    response = wrapped_callback(request, *callback_args, **callback_kwargs)
TypeError: sender() takes 0 positional arguments but 1 was given
ERROR 2019-01-29 12:24:54,184 log Internal Server Error: /api/ticket/send/
Traceback (most recent call last):
  File "/usr/local/lib/python3.6/site-packages/django/core/handlers/exception.py", line 34, in inner
    response = get_response(request)
  File "/usr/local/lib/python3.6/site-packages/django/core/handlers/base.py", line 137, in _get_response
    "returned None instead." % (callback.__module__, view_name)
ValueError: The view ticket.ticket_view.send_email.sender didn't return an HttpResponse object. It returned None instead.
<<<<<<< HEAD
>>>>>>> d396ce8204713088046b72fdca82c8f88bc08ab3
ERROR 2019-01-29 12:45:25,142 log Internal Server Error: /api/ticket/send/
Traceback (most recent call last):
  File "/usr/local/python3/lib/python3.6/site-packages/django/core/handlers/exception.py", line 34, in inner
    response = get_response(request)
  File "/usr/local/python3/lib/python3.6/site-packages/django/core/handlers/base.py", line 126, in _get_response
    response = self.process_exception_by_middleware(e, request)
  File "/usr/local/python3/lib/python3.6/site-packages/django/core/handlers/base.py", line 124, in _get_response
    response = wrapped_callback(request, *callback_args, **callback_kwargs)
TypeError: sender_email() takes 0 positional arguments but 1 was given
ERROR 2019-01-29 12:48:51,839 log Internal Server Error: /api/ticket/send/
Traceback (most recent call last):
  File "/usr/local/python3/lib/python3.6/site-packages/django/core/handlers/exception.py", line 34, in inner
    response = get_response(request)
  File "/usr/local/python3/lib/python3.6/site-packages/django/core/handlers/base.py", line 126, in _get_response
    response = self.process_exception_by_middleware(e, request)
  File "/usr/local/python3/lib/python3.6/site-packages/django/core/handlers/base.py", line 124, in _get_response
    response = wrapped_callback(request, *callback_args, **callback_kwargs)
TypeError: sender_email() takes 0 positional arguments but 1 was given
ERROR 2019-01-29 12:51:32,998 log Internal Server Error: /api/ticket/send/
Traceback (most recent call last):
  File "/usr/local/python3/lib/python3.6/site-packages/django/core/handlers/exception.py", line 34, in inner
    response = get_response(request)
  File "/usr/local/python3/lib/python3.6/site-packages/django/core/handlers/base.py", line 126, in _get_response
    response = self.process_exception_by_middleware(e, request)
  File "/usr/local/python3/lib/python3.6/site-packages/django/core/handlers/base.py", line 124, in _get_response
    response = wrapped_callback(request, *callback_args, **callback_kwargs)
TypeError: sender_email() takes 0 positional arguments but 1 was given
ERROR 2019-01-29 12:51:39,069 log Internal Server Error: /api/ticket/send/
Traceback (most recent call last):
  File "/usr/local/python3/lib/python3.6/site-packages/django/core/handlers/exception.py", line 34, in inner
    response = get_response(request)
  File "/usr/local/python3/lib/python3.6/site-packages/django/core/handlers/base.py", line 126, in _get_response
    response = self.process_exception_by_middleware(e, request)
  File "/usr/local/python3/lib/python3.6/site-packages/django/core/handlers/base.py", line 124, in _get_response
    response = wrapped_callback(request, *callback_args, **callback_kwargs)
TypeError: sender_email() takes 0 positional arguments but 1 was given
ERROR 2019-01-29 12:51:42,798 log Internal Server Error: /api/ticket/send/
Traceback (most recent call last):
  File "/usr/local/python3/lib/python3.6/site-packages/django/core/handlers/exception.py", line 34, in inner
    response = get_response(request)
  File "/usr/local/python3/lib/python3.6/site-packages/django/core/handlers/base.py", line 126, in _get_response
    response = self.process_exception_by_middleware(e, request)
  File "/usr/local/python3/lib/python3.6/site-packages/django/core/handlers/base.py", line 124, in _get_response
    response = wrapped_callback(request, *callback_args, **callback_kwargs)
TypeError: sender_email() takes 0 positional arguments but 1 was given
ERROR 2019-01-29 12:54:50,594 log Internal Server Error: /api/ticket/send/
Traceback (most recent call last):
  File "/usr/local/python3/lib/python3.6/site-packages/django/core/handlers/exception.py", line 34, in inner
    response = get_response(request)
  File "/usr/local/python3/lib/python3.6/site-packages/django/core/handlers/base.py", line 126, in _get_response
    response = self.process_exception_by_middleware(e, request)
  File "/usr/local/python3/lib/python3.6/site-packages/django/core/handlers/base.py", line 124, in _get_response
    response = wrapped_callback(request, *callback_args, **callback_kwargs)
TypeError: sender_email() takes 0 positional arguments but 1 was given
ERROR 2019-01-29 12:54:59,081 log Internal Server Error: /api/ticket/send/
Traceback (most recent call last):
  File "/usr/local/python3/lib/python3.6/site-packages/django/core/handlers/exception.py", line 34, in inner
    response = get_response(request)
  File "/usr/local/python3/lib/python3.6/site-packages/django/core/handlers/base.py", line 126, in _get_response
    response = self.process_exception_by_middleware(e, request)
  File "/usr/local/python3/lib/python3.6/site-packages/django/core/handlers/base.py", line 124, in _get_response
    response = wrapped_callback(request, *callback_args, **callback_kwargs)
TypeError: sender_email() takes 0 positional arguments but 1 was given
ERROR 2019-01-29 12:55:01,089 log Internal Server Error: /api/ticket/send/
Traceback (most recent call last):
  File "/usr/local/python3/lib/python3.6/site-packages/django/core/handlers/exception.py", line 34, in inner
    response = get_response(request)
  File "/usr/local/python3/lib/python3.6/site-packages/django/core/handlers/base.py", line 126, in _get_response
    response = self.process_exception_by_middleware(e, request)
  File "/usr/local/python3/lib/python3.6/site-packages/django/core/handlers/base.py", line 124, in _get_response
    response = wrapped_callback(request, *callback_args, **callback_kwargs)
TypeError: sender_email() takes 0 positional arguments but 1 was given
ERROR 2019-01-29 12:55:24,007 log Internal Server Error: /api/ticket/send/
Traceback (most recent call last):
  File "/usr/local/python3/lib/python3.6/site-packages/django/core/handlers/exception.py", line 34, in inner
    response = get_response(request)
  File "/usr/local/python3/lib/python3.6/site-packages/django/core/handlers/base.py", line 126, in _get_response
    response = self.process_exception_by_middleware(e, request)
  File "/usr/local/python3/lib/python3.6/site-packages/django/core/handlers/base.py", line 124, in _get_response
    response = wrapped_callback(request, *callback_args, **callback_kwargs)
TypeError: sender_email() takes 0 positional arguments but 1 was given
ERROR 2019-01-29 12:56:39,075 log Internal Server Error: /api/ticket/send/
Traceback (most recent call last):
  File "/usr/local/python3/lib/python3.6/site-packages/django/core/handlers/exception.py", line 34, in inner
    response = get_response(request)
  File "/usr/local/python3/lib/python3.6/site-packages/django/core/handlers/base.py", line 126, in _get_response
    response = self.process_exception_by_middleware(e, request)
  File "/usr/local/python3/lib/python3.6/site-packages/django/core/handlers/base.py", line 124, in _get_response
=======
ERROR 2019-01-29 12:51:56,348 log Internal Server Error: /api/ticket/send/
Traceback (most recent call last):
  File "/usr/local/lib/python3.6/site-packages/django/core/handlers/exception.py", line 34, in inner
    response = get_response(request)
  File "/usr/local/lib/python3.6/site-packages/django/core/handlers/base.py", line 126, in _get_response
    response = self.process_exception_by_middleware(e, request)
  File "/usr/local/lib/python3.6/site-packages/django/core/handlers/base.py", line 124, in _get_response
>>>>>>> 74f7d6b35876dbe7f9369b5f391533f86f89038a
    response = wrapped_callback(request, *callback_args, **callback_kwargs)
TypeError: sender_email() takes 0 positional arguments but 1 was given
ERROR 2019-01-29 16:29:10,644 log Internal Server Error: /api/home/api/
Traceback (most recent call last):
  File "/usr/local/lib/python3.6/site-packages/django/core/handlers/exception.py", line 34, in inner
    response = get_response(request)
  File "/usr/local/lib/python3.6/site-packages/django/core/handlers/base.py", line 126, in _get_response
    response = self.process_exception_by_middleware(e, request)
  File "/usr/local/lib/python3.6/site-packages/django/core/handlers/base.py", line 124, in _get_response
    response = wrapped_callback(request, *callback_args, **callback_kwargs)
  File "/Users/zhang/Documents/Python/PESCM/ticket/ticket_view/account.py", line 80, in home_api
    for user in users:
NameError: name 'users' is not defined
ERROR 2019-01-29 16:30:26,255 log Internal Server Error: /api/home/api/
Traceback (most recent call last):
  File "/usr/local/lib/python3.6/site-packages/django/core/handlers/exception.py", line 34, in inner
    response = get_response(request)
  File "/usr/local/lib/python3.6/site-packages/django/core/handlers/base.py", line 126, in _get_response
    response = self.process_exception_by_middleware(e, request)
  File "/usr/local/lib/python3.6/site-packages/django/core/handlers/base.py", line 124, in _get_response
    response = wrapped_callback(request, *callback_args, **callback_kwargs)
  File "/Users/zhang/Documents/Python/PESCM/ticket/ticket_view/account.py", line 76, in home_api
    return JsonResponse({"actions_tickets": jsonData})
  File "/usr/local/lib/python3.6/site-packages/django/http/response.py", line 558, in __init__
    data = json.dumps(data, cls=encoder, **json_dumps_params)
  File "/usr/local/Cellar/python/3.6.5/Frameworks/Python.framework/Versions/3.6/lib/python3.6/json/__init__.py", line 238, in dumps
    **kw).encode(obj)
  File "/usr/local/Cellar/python/3.6.5/Frameworks/Python.framework/Versions/3.6/lib/python3.6/json/encoder.py", line 199, in encode
    chunks = self.iterencode(o, _one_shot=True)
  File "/usr/local/Cellar/python/3.6.5/Frameworks/Python.framework/Versions/3.6/lib/python3.6/json/encoder.py", line 257, in iterencode
    return _iterencode(o, 0)
  File "/usr/local/lib/python3.6/site-packages/django/core/serializers/json.py", line 104, in default
    return super().default(o)
  File "/usr/local/Cellar/python/3.6.5/Frameworks/Python.framework/Versions/3.6/lib/python3.6/json/encoder.py", line 180, in default
    o.__class__.__name__)
TypeError: Object of type 'FieldFile' is not JSON serializable
ERROR 2019-01-29 16:31:17,723 log Internal Server Error: /api/home/api/
Traceback (most recent call last):
  File "/usr/local/lib/python3.6/site-packages/django/core/handlers/exception.py", line 34, in inner
    response = get_response(request)
  File "/usr/local/lib/python3.6/site-packages/django/core/handlers/base.py", line 126, in _get_response
    response = self.process_exception_by_middleware(e, request)
  File "/usr/local/lib/python3.6/site-packages/django/core/handlers/base.py", line 124, in _get_response
    response = wrapped_callback(request, *callback_args, **callback_kwargs)
  File "/Users/zhang/Documents/Python/PESCM/ticket/ticket_view/account.py", line 76, in home_api
    return JsonResponse({"actions_tickets": jsonData})
  File "/usr/local/lib/python3.6/site-packages/django/http/response.py", line 558, in __init__
    data = json.dumps(data, cls=encoder, **json_dumps_params)
  File "/usr/local/Cellar/python/3.6.5/Frameworks/Python.framework/Versions/3.6/lib/python3.6/json/__init__.py", line 238, in dumps
    **kw).encode(obj)
  File "/usr/local/Cellar/python/3.6.5/Frameworks/Python.framework/Versions/3.6/lib/python3.6/json/encoder.py", line 199, in encode
    chunks = self.iterencode(o, _one_shot=True)
  File "/usr/local/Cellar/python/3.6.5/Frameworks/Python.framework/Versions/3.6/lib/python3.6/json/encoder.py", line 257, in iterencode
    return _iterencode(o, 0)
  File "/usr/local/lib/python3.6/site-packages/django/core/serializers/json.py", line 104, in default
    return super().default(o)
  File "/usr/local/Cellar/python/3.6.5/Frameworks/Python.framework/Versions/3.6/lib/python3.6/json/encoder.py", line 180, in default
    o.__class__.__name__)
TypeError: Object of type 'TicketConfim' is not JSON serializable
ERROR 2019-01-29 16:54:17,074 log Internal Server Error: /api/home/api/
Traceback (most recent call last):
  File "/usr/local/lib/python3.6/site-packages/django/core/handlers/exception.py", line 34, in inner
    response = get_response(request)
  File "/usr/local/lib/python3.6/site-packages/django/core/handlers/base.py", line 126, in _get_response
    response = self.process_exception_by_middleware(e, request)
  File "/usr/local/lib/python3.6/site-packages/django/core/handlers/base.py", line 124, in _get_response
    response = wrapped_callback(request, *callback_args, **callback_kwargs)
TypeError: home_api() missing 1 required positional argument: 'callback'
ERROR 2019-01-30 09:00:40,258 log Internal Server Error: /api/home/api/
Traceback (most recent call last):
  File "/usr/local/lib/python3.6/site-packages/django/core/handlers/exception.py", line 34, in inner
    response = get_response(request)
  File "/usr/local/lib/python3.6/site-packages/django/core/handlers/base.py", line 126, in _get_response
    response = self.process_exception_by_middleware(e, request)
  File "/usr/local/lib/python3.6/site-packages/django/core/handlers/base.py", line 124, in _get_response
    response = wrapped_callback(request, *callback_args, **callback_kwargs)
TypeError: home_api() missing 1 required positional argument: 'callback'
ERROR 2019-01-30 09:04:27,471 log Internal Server Error: /api/home/api/
Traceback (most recent call last):
  File "/usr/local/lib/python3.6/site-packages/django/core/handlers/exception.py", line 34, in inner
    response = get_response(request)
  File "/usr/local/lib/python3.6/site-packages/django/core/handlers/base.py", line 126, in _get_response
    response = self.process_exception_by_middleware(e, request)
  File "/usr/local/lib/python3.6/site-packages/django/core/handlers/base.py", line 124, in _get_response
    response = wrapped_callback(request, *callback_args, **callback_kwargs)
TypeError: home_api() missing 1 required positional argument: 'callback'
ERROR 2019-01-30 09:06:56,943 log Internal Server Error: /api/home/api/
Traceback (most recent call last):
  File "/usr/local/lib/python3.6/site-packages/django/core/handlers/exception.py", line 34, in inner
    response = get_response(request)
  File "/usr/local/lib/python3.6/site-packages/django/core/handlers/base.py", line 126, in _get_response
    response = self.process_exception_by_middleware(e, request)
  File "/usr/local/lib/python3.6/site-packages/django/core/handlers/base.py", line 124, in _get_response
    response = wrapped_callback(request, *callback_args, **callback_kwargs)
TypeError: home_api() missing 1 required positional argument: 'callback'
ERROR 2019-01-30 09:08:10,902 log Internal Server Error: /api/home/api/
Traceback (most recent call last):
  File "/usr/local/lib/python3.6/site-packages/django/core/handlers/exception.py", line 34, in inner
    response = get_response(request)
  File "/usr/local/lib/python3.6/site-packages/django/core/handlers/base.py", line 126, in _get_response
    response = self.process_exception_by_middleware(e, request)
  File "/usr/local/lib/python3.6/site-packages/django/core/handlers/base.py", line 124, in _get_response
    response = wrapped_callback(request, *callback_args, **callback_kwargs)
TypeError: home_api() missing 1 required positional argument: 'callback'
ERROR 2019-01-30 09:15:59,637 log Internal Server Error: /api/home/api/
Traceback (most recent call last):
  File "/usr/local/lib/python3.6/site-packages/django/core/handlers/exception.py", line 34, in inner
    response = get_response(request)
  File "/usr/local/lib/python3.6/site-packages/django/core/handlers/base.py", line 126, in _get_response
    response = self.process_exception_by_middleware(e, request)
  File "/usr/local/lib/python3.6/site-packages/django/core/handlers/base.py", line 124, in _get_response
    response = wrapped_callback(request, *callback_args, **callback_kwargs)
TypeError: home_api() missing 1 required positional argument: 'callback'
ERROR 2019-01-30 09:16:22,753 log Internal Server Error: /api/home/api/
Traceback (most recent call last):
  File "/usr/local/lib/python3.6/site-packages/django/core/handlers/exception.py", line 34, in inner
    response = get_response(request)
  File "/usr/local/lib/python3.6/site-packages/django/core/handlers/base.py", line 126, in _get_response
    response = self.process_exception_by_middleware(e, request)
  File "/usr/local/lib/python3.6/site-packages/django/core/handlers/base.py", line 124, in _get_response
    response = wrapped_callback(request, *callback_args, **callback_kwargs)
TypeError: home_api() missing 1 required positional argument: 'callback'
ERROR 2019-01-30 09:16:50,028 log Internal Server Error: /api/home/api/
Traceback (most recent call last):
  File "/usr/local/lib/python3.6/site-packages/django/core/handlers/exception.py", line 34, in inner
    response = get_response(request)
  File "/usr/local/lib/python3.6/site-packages/django/core/handlers/base.py", line 126, in _get_response
    response = self.process_exception_by_middleware(e, request)
  File "/usr/local/lib/python3.6/site-packages/django/core/handlers/base.py", line 124, in _get_response
    response = wrapped_callback(request, *callback_args, **callback_kwargs)
  File "/Users/zhang/Documents/Python/PESCM/ticket/ticket_view/account.py", line 76, in home_api
    return JsonResponse({"actions_tickets": jsonData})
NameError: name 'callback' is not defined
ERROR 2019-01-30 09:16:53,969 log Internal Server Error: /api/home/api/
Traceback (most recent call last):
  File "/usr/local/lib/python3.6/site-packages/django/core/handlers/exception.py", line 34, in inner
    response = get_response(request)
  File "/usr/local/lib/python3.6/site-packages/django/core/handlers/base.py", line 126, in _get_response
    response = self.process_exception_by_middleware(e, request)
  File "/usr/local/lib/python3.6/site-packages/django/core/handlers/base.py", line 124, in _get_response
    response = wrapped_callback(request, *callback_args, **callback_kwargs)
  File "/Users/zhang/Documents/Python/PESCM/ticket/ticket_view/account.py", line 76, in home_api
    return JsonResponse({"actions_tickets": jsonData})
NameError: name 'callback' is not defined
ERROR 2019-01-30 09:17:11,584 log Internal Server Error: /api/home/api/
Traceback (most recent call last):
  File "/usr/local/lib/python3.6/site-packages/django/core/handlers/exception.py", line 34, in inner
    response = get_response(request)
  File "/usr/local/lib/python3.6/site-packages/django/core/handlers/base.py", line 126, in _get_response
    response = self.process_exception_by_middleware(e, request)
  File "/usr/local/lib/python3.6/site-packages/django/core/handlers/base.py", line 124, in _get_response
    response = wrapped_callback(request, *callback_args, **callback_kwargs)
  File "/Users/zhang/Documents/Python/PESCM/ticket/ticket_view/account.py", line 76, in home_api
    return JsonResponse({"actions_tickets": jsonData})
NameError: name 'callback' is not defined
ERROR 2019-01-30 09:17:50,508 log Internal Server Error: /api/home/api/
Traceback (most recent call last):
  File "/usr/local/lib/python3.6/site-packages/django/core/handlers/exception.py", line 34, in inner
    response = get_response(request)
  File "/usr/local/lib/python3.6/site-packages/django/core/handlers/base.py", line 126, in _get_response
    response = self.process_exception_by_middleware(e, request)
  File "/usr/local/lib/python3.6/site-packages/django/core/handlers/base.py", line 124, in _get_response
    response = wrapped_callback(request, *callback_args, **callback_kwargs)
  File "/Users/zhang/Documents/Python/PESCM/ticket/ticket_view/account.py", line 76, in home_api
    return JsonResponse({"actions_tickets": jsonData})
NameError: name 'callback' is not defined
WARNING 2019-01-30 09:47:11,603 log Not Found: /jq-paginator.js
WARNING 2019-01-30 09:47:13,062 log Not Found: /jq-paginator.js
ERROR 2019-01-30 10:35:36,320 log Internal Server Error: /api/ticket/server/detail/
Traceback (most recent call last):
  File "/usr/local/lib/python3.6/site-packages/django/core/handlers/exception.py", line 34, in inner
    response = get_response(request)
  File "/usr/local/lib/python3.6/site-packages/django/core/handlers/base.py", line 126, in _get_response
    response = self.process_exception_by_middleware(e, request)
  File "/usr/local/lib/python3.6/site-packages/django/core/handlers/base.py", line 124, in _get_response
    response = wrapped_callback(request, *callback_args, **callback_kwargs)
  File "/usr/local/lib/python3.6/site-packages/django/views/generic/base.py", line 68, in view
    return self.dispatch(request, *args, **kwargs)
  File "/usr/local/lib/python3.6/site-packages/django/views/generic/base.py", line 88, in dispatch
    return handler(request, *args, **kwargs)
  File "/Users/zhang/Documents/Python/PESCM/ticket/ticket_view/ticket.py", line 325, in get
    ticket = Ticket.objects.get(ticket_id=request.GET.get('ticket_id'))
  File "/usr/local/lib/python3.6/site-packages/django/db/models/manager.py", line 82, in manager_method
    return getattr(self.get_queryset(), name)(*args, **kwargs)
  File "/usr/local/lib/python3.6/site-packages/django/db/models/query.py", line 390, in get
    clone = self.filter(*args, **kwargs)
  File "/usr/local/lib/python3.6/site-packages/django/db/models/query.py", line 844, in filter
    return self._filter_or_exclude(False, *args, **kwargs)
  File "/usr/local/lib/python3.6/site-packages/django/db/models/query.py", line 862, in _filter_or_exclude
    clone.query.add_q(Q(*args, **kwargs))
  File "/usr/local/lib/python3.6/site-packages/django/db/models/sql/query.py", line 1263, in add_q
    clause, _ = self._add_q(q_object, self.used_aliases)
  File "/usr/local/lib/python3.6/site-packages/django/db/models/sql/query.py", line 1287, in _add_q
    split_subq=split_subq,
  File "/usr/local/lib/python3.6/site-packages/django/db/models/sql/query.py", line 1225, in build_filter
    condition = self.build_lookup(lookups, col, value)
  File "/usr/local/lib/python3.6/site-packages/django/db/models/sql/query.py", line 1096, in build_lookup
    lookup = lookup_class(lhs, rhs)
  File "/usr/local/lib/python3.6/site-packages/django/db/models/lookups.py", line 20, in __init__
    self.rhs = self.get_prep_lookup()
  File "/usr/local/lib/python3.6/site-packages/django/db/models/lookups.py", line 70, in get_prep_lookup
    return self.lhs.output_field.get_prep_value(self.rhs)
  File "/usr/local/lib/python3.6/site-packages/django/db/models/fields/__init__.py", line 965, in get_prep_value
    return int(value)
ValueError: invalid literal for int() with base 10: ''
ERROR 2019-01-30 10:36:15,559 log Internal Server Error: /api/ticket/server/detail/
Traceback (most recent call last):
  File "/usr/local/lib/python3.6/site-packages/django/core/handlers/exception.py", line 34, in inner
    response = get_response(request)
  File "/usr/local/lib/python3.6/site-packages/django/core/handlers/base.py", line 126, in _get_response
    response = self.process_exception_by_middleware(e, request)
  File "/usr/local/lib/python3.6/site-packages/django/core/handlers/base.py", line 124, in _get_response
    response = wrapped_callback(request, *callback_args, **callback_kwargs)
  File "/usr/local/lib/python3.6/site-packages/django/views/generic/base.py", line 68, in view
    return self.dispatch(request, *args, **kwargs)
  File "/usr/local/lib/python3.6/site-packages/django/views/generic/base.py", line 88, in dispatch
    return handler(request, *args, **kwargs)
  File "/Users/zhang/Documents/Python/PESCM/ticket/ticket_view/ticket.py", line 325, in get
    ticket = Ticket.objects.get(ticket_id=request.GET.get('ticket_id'))
  File "/usr/local/lib/python3.6/site-packages/django/db/models/manager.py", line 82, in manager_method
    return getattr(self.get_queryset(), name)(*args, **kwargs)
  File "/usr/local/lib/python3.6/site-packages/django/db/models/query.py", line 390, in get
    clone = self.filter(*args, **kwargs)
  File "/usr/local/lib/python3.6/site-packages/django/db/models/query.py", line 844, in filter
    return self._filter_or_exclude(False, *args, **kwargs)
  File "/usr/local/lib/python3.6/site-packages/django/db/models/query.py", line 862, in _filter_or_exclude
    clone.query.add_q(Q(*args, **kwargs))
  File "/usr/local/lib/python3.6/site-packages/django/db/models/sql/query.py", line 1263, in add_q
    clause, _ = self._add_q(q_object, self.used_aliases)
  File "/usr/local/lib/python3.6/site-packages/django/db/models/sql/query.py", line 1287, in _add_q
    split_subq=split_subq,
  File "/usr/local/lib/python3.6/site-packages/django/db/models/sql/query.py", line 1225, in build_filter
    condition = self.build_lookup(lookups, col, value)
  File "/usr/local/lib/python3.6/site-packages/django/db/models/sql/query.py", line 1096, in build_lookup
    lookup = lookup_class(lhs, rhs)
  File "/usr/local/lib/python3.6/site-packages/django/db/models/lookups.py", line 20, in __init__
    self.rhs = self.get_prep_lookup()
  File "/usr/local/lib/python3.6/site-packages/django/db/models/lookups.py", line 70, in get_prep_lookup
    return self.lhs.output_field.get_prep_value(self.rhs)
  File "/usr/local/lib/python3.6/site-packages/django/db/models/fields/__init__.py", line 965, in get_prep_value
    return int(value)
ValueError: invalid literal for int() with base 10: ''
ERROR 2019-01-30 10:37:07,256 log Internal Server Error: /api/ticket/server/detail/
Traceback (most recent call last):
  File "/usr/local/lib/python3.6/site-packages/django/core/handlers/exception.py", line 34, in inner
    response = get_response(request)
  File "/usr/local/lib/python3.6/site-packages/django/core/handlers/base.py", line 126, in _get_response
    response = self.process_exception_by_middleware(e, request)
  File "/usr/local/lib/python3.6/site-packages/django/core/handlers/base.py", line 124, in _get_response
    response = wrapped_callback(request, *callback_args, **callback_kwargs)
  File "/usr/local/lib/python3.6/site-packages/django/views/generic/base.py", line 68, in view
    return self.dispatch(request, *args, **kwargs)
  File "/usr/local/lib/python3.6/site-packages/django/views/generic/base.py", line 88, in dispatch
    return handler(request, *args, **kwargs)
  File "/Users/zhang/Documents/Python/PESCM/ticket/ticket_view/ticket.py", line 325, in get
    ticket = Ticket.objects.get(ticket_id=request.GET.get('ticket_id'))
  File "/usr/local/lib/python3.6/site-packages/django/db/models/manager.py", line 82, in manager_method
    return getattr(self.get_queryset(), name)(*args, **kwargs)
  File "/usr/local/lib/python3.6/site-packages/django/db/models/query.py", line 390, in get
    clone = self.filter(*args, **kwargs)
  File "/usr/local/lib/python3.6/site-packages/django/db/models/query.py", line 844, in filter
    return self._filter_or_exclude(False, *args, **kwargs)
  File "/usr/local/lib/python3.6/site-packages/django/db/models/query.py", line 862, in _filter_or_exclude
    clone.query.add_q(Q(*args, **kwargs))
  File "/usr/local/lib/python3.6/site-packages/django/db/models/sql/query.py", line 1263, in add_q
    clause, _ = self._add_q(q_object, self.used_aliases)
  File "/usr/local/lib/python3.6/site-packages/django/db/models/sql/query.py", line 1287, in _add_q
    split_subq=split_subq,
  File "/usr/local/lib/python3.6/site-packages/django/db/models/sql/query.py", line 1225, in build_filter
    condition = self.build_lookup(lookups, col, value)
  File "/usr/local/lib/python3.6/site-packages/django/db/models/sql/query.py", line 1096, in build_lookup
    lookup = lookup_class(lhs, rhs)
  File "/usr/local/lib/python3.6/site-packages/django/db/models/lookups.py", line 20, in __init__
    self.rhs = self.get_prep_lookup()
  File "/usr/local/lib/python3.6/site-packages/django/db/models/lookups.py", line 70, in get_prep_lookup
    return self.lhs.output_field.get_prep_value(self.rhs)
  File "/usr/local/lib/python3.6/site-packages/django/db/models/fields/__init__.py", line 965, in get_prep_value
    return int(value)
ValueError: invalid literal for int() with base 10: ''
WARNING 2019-03-04 16:12:32,874 log Not Found: /
WARNING 2019-03-04 16:12:35,576 log Not Found: /favicon.ico
ERROR 2019-03-04 16:41:20,084 log Internal Server Error: /xadmin/
Traceback (most recent call last):
  File "/usr/local/lib/python3.6/site-packages/django/core/handlers/exception.py", line 34, in inner
    response = get_response(request)
  File "/usr/local/lib/python3.6/site-packages/django/core/handlers/base.py", line 126, in _get_response
    response = self.process_exception_by_middleware(e, request)
  File "/usr/local/lib/python3.6/site-packages/django/core/handlers/base.py", line 124, in _get_response
    response = wrapped_callback(request, *callback_args, **callback_kwargs)
  File "/usr/local/lib/python3.6/site-packages/xadmin/sites.py", line 300, in wrapper
    return self.admin_view(view, cacheable)(*args, **kwargs)
  File "/usr/local/lib/python3.6/site-packages/django/views/decorators/cache.py", line 44, in _wrapped_view_func
    response = view_func(request, *args, **kwargs)
  File "/usr/local/lib/python3.6/site-packages/xadmin/sites.py", line 208, in inner
    return view(request, *args, **kwargs)
  File "/usr/local/lib/python3.6/site-packages/xadmin/views/base.py", line 282, in view
    return handler(request, *args, **kwargs)
  File "/usr/local/lib/python3.6/site-packages/django/views/decorators/cache.py", line 44, in _wrapped_view_func
    response = view_func(request, *args, **kwargs)
  File "/usr/local/lib/python3.6/site-packages/xadmin/views/dashboard.py", line 592, in get
    self.widgets = self.get_widgets()
  File "/usr/local/lib/python3.6/site-packages/xadmin/views/base.py", line 80, in method
    return filter_chain(filters, len(filters) - 1, _inner_method, *args, **kwargs)
  File "/usr/local/lib/python3.6/site-packages/xadmin/views/base.py", line 49, in filter_chain
    return func()
  File "/usr/local/lib/python3.6/site-packages/xadmin/views/base.py", line 74, in _inner_method
    return func(self, *args, **kwargs)
  File "/usr/local/lib/python3.6/site-packages/xadmin/views/dashboard.py", line 548, in get_widgets
    user=self.user, key=self.get_portal_key())
  File "/usr/local/lib/python3.6/site-packages/django/db/models/manager.py", line 82, in manager_method
    return getattr(self.get_queryset(), name)(*args, **kwargs)
  File "/usr/local/lib/python3.6/site-packages/django/db/models/query.py", line 844, in filter
    return self._filter_or_exclude(False, *args, **kwargs)
  File "/usr/local/lib/python3.6/site-packages/django/db/models/query.py", line 862, in _filter_or_exclude
    clone.query.add_q(Q(*args, **kwargs))
  File "/usr/local/lib/python3.6/site-packages/django/db/models/sql/query.py", line 1263, in add_q
    clause, _ = self._add_q(q_object, self.used_aliases)
  File "/usr/local/lib/python3.6/site-packages/django/db/models/sql/query.py", line 1287, in _add_q
    split_subq=split_subq,
  File "/usr/local/lib/python3.6/site-packages/django/db/models/sql/query.py", line 1198, in build_filter
    self.check_related_objects(join_info.final_field, value, join_info.opts)
  File "/usr/local/lib/python3.6/site-packages/django/db/models/sql/query.py", line 1065, in check_related_objects
    for v in value:
  File "/usr/local/lib/python3.6/site-packages/django/utils/functional.py", line 214, in inner
    return func(self._wrapped, *args)
TypeError: 'AnonymousUser' object is not iterable
WARNING 2019-03-04 16:41:49,653 log Not Found: /favicon.ico
WARNING 2019-03-04 16:41:57,031 log Not Found: /favicon.ico
WARNING 2019-03-04 16:42:00,499 log Not Found: /favicon.ico
WARNING 2019-03-04 16:43:16,183 log Not Found: /favicon.ico
WARNING 2019-03-04 16:44:35,154 log Not Found: /favicon.ico
WARNING 2019-03-04 16:44:38,343 log Not Found: /favicon.ico
WARNING 2019-03-04 16:45:21,867 log Not Found: /
WARNING 2019-03-04 16:45:22,055 log Not Found: /favicon.ico
WARNING 2019-03-04 16:45:25,136 log Not Found: /favicon.ico
WARNING 2019-03-04 16:45:30,102 log Not Found: /favicon.ico
WARNING 2019-03-04 16:45:37,231 log Not Found: /favicon.ico
WARNING 2019-03-04 16:45:47,594 log Not Found: /favicon.ico
WARNING 2019-03-04 16:46:06,478 log Not Found: /favicon.ico
WARNING 2019-03-04 16:46:28,459 log Not Found: /favicon.ico
WARNING 2019-03-04 16:46:31,848 log Not Found: /favicon.ico
WARNING 2019-03-04 16:46:35,729 log Not Found: /favicon.ico
WARNING 2019-03-04 16:49:32,470 log Not Found: /favicon.ico
WARNING 2019-03-04 16:53:33,134 log Not Found: /favicon.ico
WARNING 2019-03-04 16:53:44,743 log Not Found: /favicon.ico
WARNING 2019-03-04 16:53:56,827 log Not Found: /favicon.ico
WARNING 2019-03-04 16:54:05,535 log Not Found: /favicon.ico
WARNING 2019-03-04 16:54:07,148 log Not Found: /favicon.ico
WARNING 2019-03-04 16:54:35,800 log Not Found: /favicon.ico
WARNING 2019-03-04 16:54:38,358 log Not Found: /favicon.ico
WARNING 2019-03-04 16:54:43,258 log Not Found: /favicon.ico
WARNING 2019-03-04 16:54:50,328 log Not Found: /favicon.ico
WARNING 2019-03-04 16:57:45,885 log Not Found: /favicon.ico
WARNING 2019-03-04 16:57:47,582 log Not Found: /favicon.ico
WARNING 2019-03-04 16:57:49,538 log Not Found: /favicon.ico
WARNING 2019-03-04 16:58:29,460 log Not Found: /favicon.ico
ERROR 2019-03-04 17:13:32,062 log Internal Server Error: /api/ticket/server/detail/
Traceback (most recent call last):
  File "/usr/local/lib/python3.6/site-packages/django/utils/datastructures.py", line 77, in __getitem__
    list_ = super().__getitem__(key)
KeyError: 'dev_push_time'

During handling of the above exception, another exception occurred:

Traceback (most recent call last):
  File "/usr/local/lib/python3.6/site-packages/django/core/handlers/exception.py", line 34, in inner
    response = get_response(request)
  File "/usr/local/lib/python3.6/site-packages/django/core/handlers/base.py", line 126, in _get_response
    response = self.process_exception_by_middleware(e, request)
  File "/usr/local/lib/python3.6/site-packages/django/core/handlers/base.py", line 124, in _get_response
    response = wrapped_callback(request, *callback_args, **callback_kwargs)
  File "/usr/local/lib/python3.6/site-packages/django/views/generic/base.py", line 68, in view
    return self.dispatch(request, *args, **kwargs)
  File "/usr/local/lib/python3.6/site-packages/django/views/generic/base.py", line 88, in dispatch
    return handler(request, *args, **kwargs)
  File "/Users/zhang/Documents/Python/PESCM/ticket/ticket_view/ticket.py", line 356, in post
    if tickt_form.data['dev_push_time'] is not '':
  File "/usr/local/lib/python3.6/site-packages/django/utils/datastructures.py", line 79, in __getitem__
    raise MultiValueDictKeyError(key)
django.utils.datastructures.MultiValueDictKeyError: 'dev_push_time'
ERROR 2019-03-04 17:14:06,681 log Internal Server Error: /api/ticket/server/detail/
Traceback (most recent call last):
  File "/usr/local/lib/python3.6/site-packages/django/utils/datastructures.py", line 77, in __getitem__
    list_ = super().__getitem__(key)
KeyError: 'dev_push_time'

During handling of the above exception, another exception occurred:

Traceback (most recent call last):
  File "/usr/local/lib/python3.6/site-packages/django/core/handlers/exception.py", line 34, in inner
    response = get_response(request)
  File "/usr/local/lib/python3.6/site-packages/django/core/handlers/base.py", line 126, in _get_response
    response = self.process_exception_by_middleware(e, request)
  File "/usr/local/lib/python3.6/site-packages/django/core/handlers/base.py", line 124, in _get_response
    response = wrapped_callback(request, *callback_args, **callback_kwargs)
  File "/usr/local/lib/python3.6/site-packages/django/views/generic/base.py", line 68, in view
    return self.dispatch(request, *args, **kwargs)
  File "/usr/local/lib/python3.6/site-packages/django/views/generic/base.py", line 88, in dispatch
    return handler(request, *args, **kwargs)
  File "/Users/zhang/Documents/Python/PESCM/ticket/ticket_view/ticket.py", line 356, in post
    if tickt_form.data['dev_push_time'] is not '':
  File "/usr/local/lib/python3.6/site-packages/django/utils/datastructures.py", line 79, in __getitem__
    raise MultiValueDictKeyError(key)
django.utils.datastructures.MultiValueDictKeyError: 'dev_push_time'
ERROR 2019-03-04 17:15:20,697 log Internal Server Error: /api/ticket/server/detail/
Traceback (most recent call last):
  File "/usr/local/lib/python3.6/site-packages/django/utils/datastructures.py", line 77, in __getitem__
    list_ = super().__getitem__(key)
KeyError: 'dev_push_time'

During handling of the above exception, another exception occurred:

Traceback (most recent call last):
  File "/usr/local/lib/python3.6/site-packages/django/core/handlers/exception.py", line 34, in inner
    response = get_response(request)
  File "/usr/local/lib/python3.6/site-packages/django/core/handlers/base.py", line 126, in _get_response
    response = self.process_exception_by_middleware(e, request)
  File "/usr/local/lib/python3.6/site-packages/django/core/handlers/base.py", line 124, in _get_response
    response = wrapped_callback(request, *callback_args, **callback_kwargs)
  File "/usr/local/lib/python3.6/site-packages/django/views/generic/base.py", line 68, in view
    return self.dispatch(request, *args, **kwargs)
  File "/usr/local/lib/python3.6/site-packages/django/views/generic/base.py", line 88, in dispatch
    return handler(request, *args, **kwargs)
  File "/Users/zhang/Documents/Python/PESCM/ticket/ticket_view/ticket.py", line 356, in post
    if tickt_form.data['dev_push_time'] is not '':
  File "/usr/local/lib/python3.6/site-packages/django/utils/datastructures.py", line 79, in __getitem__
    raise MultiValueDictKeyError(key)
django.utils.datastructures.MultiValueDictKeyError: 'dev_push_time'
WARNING 2019-03-04 17:18:53,297 log Not Found: /favicon.ico
WARNING 2019-03-04 17:18:55,242 log Not Found: /favicon.ico
WARNING 2019-03-04 17:18:56,439 log Not Found: /favicon.ico
WARNING 2019-03-04 17:18:57,346 log Not Found: /favicon.ico
WARNING 2019-03-04 17:19:52,907 log Not Found: /apple-touch-icon-precomposed.png
WARNING 2019-03-04 17:19:52,940 log Not Found: /apple-touch-icon.png
WARNING 2019-03-04 17:19:52,964 log Not Found: /favicon.ico
WARNING 2019-03-04 17:19:52,989 log Not Found: /apple-touch-icon-precomposed.png
WARNING 2019-03-04 17:19:53,013 log Not Found: /apple-touch-icon.png
WARNING 2019-03-04 17:19:53,038 log Not Found: /favicon.ico
WARNING 2019-03-04 17:19:53,093 log Not Found: /apple-touch-icon-precomposed.png
WARNING 2019-03-04 17:19:53,121 log Not Found: /apple-touch-icon.png
WARNING 2019-03-04 17:19:53,149 log Not Found: /favicon.ico
WARNING 2019-03-04 17:19:53,182 log Not Found: /apple-touch-icon-precomposed.png
WARNING 2019-03-04 17:19:53,223 log Not Found: /apple-touch-icon.png
WARNING 2019-03-04 17:19:53,273 log Not Found: /favicon.ico
WARNING 2019-03-04 17:19:54,273 log Not Found: /favicon.ico
WARNING 2019-03-04 17:19:54,357 log Not Found: /apple-touch-icon-precomposed.png
WARNING 2019-03-04 17:19:54,386 log Not Found: /apple-touch-icon.png
WARNING 2019-03-04 17:21:44,131 log Not Found: /favicon.ico
WARNING 2019-03-04 17:21:50,462 log Not Found: /favicon.ico
WARNING 2019-03-04 17:21:53,930 log Not Found: /favicon.ico
WARNING 2019-03-04 17:22:07,888 log Not Found: /favicon.ico
ERROR 2019-03-04 18:01:15,058 log Internal Server Error: /api/ticket/server/detail/
Traceback (most recent call last):
  File "/usr/local/lib/python3.6/site-packages/django/utils/datastructures.py", line 77, in __getitem__
    list_ = super().__getitem__(key)
KeyError: 'dev_push_time'

During handling of the above exception, another exception occurred:

Traceback (most recent call last):
  File "/usr/local/lib/python3.6/site-packages/django/core/handlers/exception.py", line 34, in inner
    response = get_response(request)
  File "/usr/local/lib/python3.6/site-packages/django/core/handlers/base.py", line 126, in _get_response
    response = self.process_exception_by_middleware(e, request)
  File "/usr/local/lib/python3.6/site-packages/django/core/handlers/base.py", line 124, in _get_response
    response = wrapped_callback(request, *callback_args, **callback_kwargs)
  File "/usr/local/lib/python3.6/site-packages/django/views/generic/base.py", line 68, in view
    return self.dispatch(request, *args, **kwargs)
  File "/usr/local/lib/python3.6/site-packages/django/views/generic/base.py", line 88, in dispatch
    return handler(request, *args, **kwargs)
  File "/Users/zhang/Documents/Python/PESCM/ticket/ticket_view/ticket.py", line 356, in post
    if tickt_form.data['dev_push_time'] is not '':
  File "/usr/local/lib/python3.6/site-packages/django/utils/datastructures.py", line 79, in __getitem__
    raise MultiValueDictKeyError(key)
django.utils.datastructures.MultiValueDictKeyError: 'dev_push_time'
ERROR 2019-03-04 18:01:46,263 log Internal Server Error: /api/ticket/server/detail/
Traceback (most recent call last):
  File "/usr/local/lib/python3.6/site-packages/django/core/handlers/exception.py", line 34, in inner
    response = get_response(request)
  File "/usr/local/lib/python3.6/site-packages/django/core/handlers/base.py", line 126, in _get_response
    response = self.process_exception_by_middleware(e, request)
  File "/usr/local/lib/python3.6/site-packages/django/core/handlers/base.py", line 124, in _get_response
    response = wrapped_callback(request, *callback_args, **callback_kwargs)
  File "/usr/local/lib/python3.6/site-packages/django/views/generic/base.py", line 68, in view
    return self.dispatch(request, *args, **kwargs)
  File "/usr/local/lib/python3.6/site-packages/django/views/generic/base.py", line 88, in dispatch
    return handler(request, *args, **kwargs)
  File "/Users/zhang/Documents/Python/PESCM/ticket/ticket_view/ticket.py", line 345, in post
    print(request.POST.get['ticket_listsort'])
TypeError: 'method' object is not subscriptable
ERROR 2019-03-04 18:04:36,869 log Internal Server Error: /api/ticket/server/detail/
Traceback (most recent call last):
  File "/usr/local/lib/python3.6/site-packages/django/utils/datastructures.py", line 77, in __getitem__
    list_ = super().__getitem__(key)
KeyError: 'dev_push_time'

During handling of the above exception, another exception occurred:

Traceback (most recent call last):
  File "/usr/local/lib/python3.6/site-packages/django/core/handlers/exception.py", line 34, in inner
    response = get_response(request)
  File "/usr/local/lib/python3.6/site-packages/django/core/handlers/base.py", line 126, in _get_response
    response = self.process_exception_by_middleware(e, request)
  File "/usr/local/lib/python3.6/site-packages/django/core/handlers/base.py", line 124, in _get_response
    response = wrapped_callback(request, *callback_args, **callback_kwargs)
  File "/usr/local/lib/python3.6/site-packages/django/views/generic/base.py", line 68, in view
    return self.dispatch(request, *args, **kwargs)
  File "/usr/local/lib/python3.6/site-packages/django/views/generic/base.py", line 88, in dispatch
    return handler(request, *args, **kwargs)
  File "/Users/zhang/Documents/Python/PESCM/ticket/ticket_view/ticket.py", line 363, in post
    if tickt_form.data['dev_push_time'] is not '':
  File "/usr/local/lib/python3.6/site-packages/django/utils/datastructures.py", line 79, in __getitem__
    raise MultiValueDictKeyError(key)
django.utils.datastructures.MultiValueDictKeyError: 'dev_push_time'
ERROR 2019-03-04 18:05:55,604 log Internal Server Error: /api/ticket/server/detail/
Traceback (most recent call last):
  File "/usr/local/lib/python3.6/site-packages/django/utils/datastructures.py", line 77, in __getitem__
    list_ = super().__getitem__(key)
KeyError: 'dev_push_time'

During handling of the above exception, another exception occurred:

Traceback (most recent call last):
  File "/usr/local/lib/python3.6/site-packages/django/core/handlers/exception.py", line 34, in inner
    response = get_response(request)
  File "/usr/local/lib/python3.6/site-packages/django/core/handlers/base.py", line 126, in _get_response
    response = self.process_exception_by_middleware(e, request)
  File "/usr/local/lib/python3.6/site-packages/django/core/handlers/base.py", line 124, in _get_response
    response = wrapped_callback(request, *callback_args, **callback_kwargs)
  File "/usr/local/lib/python3.6/site-packages/django/views/generic/base.py", line 68, in view
    return self.dispatch(request, *args, **kwargs)
  File "/usr/local/lib/python3.6/site-packages/django/views/generic/base.py", line 88, in dispatch
    return handler(request, *args, **kwargs)
  File "/Users/zhang/Documents/Python/PESCM/ticket/ticket_view/ticket.py", line 363, in post
    if tickt_form.data['dev_push_time'] is not '':
  File "/usr/local/lib/python3.6/site-packages/django/utils/datastructures.py", line 79, in __getitem__
    raise MultiValueDictKeyError(key)
django.utils.datastructures.MultiValueDictKeyError: 'dev_push_time'
ERROR 2019-03-04 18:06:52,883 log Internal Server Error: /api/ticket/server/detail/
Traceback (most recent call last):
  File "/usr/local/lib/python3.6/site-packages/django/utils/datastructures.py", line 77, in __getitem__
    list_ = super().__getitem__(key)
KeyError: 'ticket_content'

During handling of the above exception, another exception occurred:

Traceback (most recent call last):
  File "/usr/local/lib/python3.6/site-packages/django/core/handlers/exception.py", line 34, in inner
    response = get_response(request)
  File "/usr/local/lib/python3.6/site-packages/django/core/handlers/base.py", line 126, in _get_response
    response = self.process_exception_by_middleware(e, request)
  File "/usr/local/lib/python3.6/site-packages/django/core/handlers/base.py", line 124, in _get_response
    response = wrapped_callback(request, *callback_args, **callback_kwargs)
  File "/usr/local/lib/python3.6/site-packages/django/views/generic/base.py", line 68, in view
    return self.dispatch(request, *args, **kwargs)
  File "/usr/local/lib/python3.6/site-packages/django/views/generic/base.py", line 88, in dispatch
    return handler(request, *args, **kwargs)
  File "/Users/zhang/Documents/Python/PESCM/ticket/ticket_view/ticket.py", line 377, in post
    ticket_confirm.content = tickt_form.data['ticket_content']
  File "/usr/local/lib/python3.6/site-packages/django/utils/datastructures.py", line 79, in __getitem__
    raise MultiValueDictKeyError(key)
django.utils.datastructures.MultiValueDictKeyError: 'ticket_content'
ERROR 2019-03-04 18:23:47,324 log Internal Server Error: /api/ticket/server/detail/
Traceback (most recent call last):
  File "/usr/local/lib/python3.6/site-packages/django/utils/datastructures.py", line 77, in __getitem__
    list_ = super().__getitem__(key)
KeyError: 'dev_push_time'

During handling of the above exception, another exception occurred:

Traceback (most recent call last):
  File "/usr/local/lib/python3.6/site-packages/django/core/handlers/exception.py", line 34, in inner
    response = get_response(request)
  File "/usr/local/lib/python3.6/site-packages/django/core/handlers/base.py", line 126, in _get_response
    response = self.process_exception_by_middleware(e, request)
  File "/usr/local/lib/python3.6/site-packages/django/core/handlers/base.py", line 124, in _get_response
    response = wrapped_callback(request, *callback_args, **callback_kwargs)
  File "/usr/local/lib/python3.6/site-packages/django/views/generic/base.py", line 68, in view
    return self.dispatch(request, *args, **kwargs)
  File "/usr/local/lib/python3.6/site-packages/django/views/generic/base.py", line 88, in dispatch
    return handler(request, *args, **kwargs)
  File "/Users/zhang/Documents/Python/PESCM/ticket/ticket_view/ticket.py", line 357, in post
    if tickt_form.data['dev_push_time'] is not '':
  File "/usr/local/lib/python3.6/site-packages/django/utils/datastructures.py", line 79, in __getitem__
    raise MultiValueDictKeyError(key)
django.utils.datastructures.MultiValueDictKeyError: 'dev_push_time'
WARNING 2019-03-05 08:27:53,469 log Not Found: /api/api/login/
WARNING 2019-03-05 08:57:39,866 log Not Found: /favicon.ico
WARNING 2019-03-05 08:57:49,933 log Not Found: /favicon.ico
WARNING 2019-03-05 09:03:53,259 log Not Found: /favicon.ico
WARNING 2019-03-05 09:54:54,552 log Forbidden (Permission denied): /xadmin/ticket/account/
Traceback (most recent call last):
  File "/usr/local/lib/python3.6/site-packages/django/core/handlers/exception.py", line 34, in inner
    response = get_response(request)
  File "/usr/local/lib/python3.6/site-packages/django/core/handlers/base.py", line 126, in _get_response
    response = self.process_exception_by_middleware(e, request)
  File "/usr/local/lib/python3.6/site-packages/django/core/handlers/base.py", line 124, in _get_response
    response = wrapped_callback(request, *callback_args, **callback_kwargs)
  File "/usr/local/lib/python3.6/site-packages/xadmin/sites.py", line 300, in wrapper
    return self.admin_view(view, cacheable)(*args, **kwargs)
  File "/usr/local/lib/python3.6/site-packages/django/views/decorators/cache.py", line 44, in _wrapped_view_func
    response = view_func(request, *args, **kwargs)
  File "/usr/local/lib/python3.6/site-packages/xadmin/sites.py", line 208, in inner
    return view(request, *args, **kwargs)
  File "/usr/local/lib/python3.6/site-packages/xadmin/views/base.py", line 271, in view
    self = cls(request, *args, **kwargs)
  File "/usr/local/lib/python3.6/site-packages/xadmin/views/base.py", line 497, in __init__
    super(ModelAdminView, self).__init__(request, *args, **kwargs)
  File "/usr/local/lib/python3.6/site-packages/xadmin/views/base.py", line 266, in __init__
    self.init_request(*args, **kwargs)
  File "/usr/local/lib/python3.6/site-packages/xadmin/views/list.py", line 122, in init_request
    raise PermissionDenied
django.core.exceptions.PermissionDenied
WARNING 2019-03-05 09:54:55,118 log Not Found: /xadmin/static/server_images/error.jpeg
WARNING 2019-03-05 09:55:09,478 log Not Found: /favicon.ico
WARNING 2019-03-05 09:55:26,093 log Not Found: /uploads/image/default.png
WARNING 2019-03-05 09:56:06,817 log Not Found: /uploads/image/default.png
WARNING 2019-03-05 17:32:28,000 log Not Found: /api/api/login/
WARNING 2019-03-05 17:32:28,237 log Not Found: /favicon.ico
WARNING 2019-03-05 17:32:42,964 log Not Found: /favicon.ico
WARNING 2019-03-05 17:32:58,045 log Not Found: /favicon.ico
ERROR 2019-03-05 17:50:58,222 log Internal Server Error: /api/ticket/detail/
Traceback (most recent call last):
  File "/usr/local/lib/python3.6/site-packages/django/core/handlers/exception.py", line 34, in inner
    response = get_response(request)
  File "/usr/local/lib/python3.6/site-packages/django/core/handlers/base.py", line 126, in _get_response
    response = self.process_exception_by_middleware(e, request)
  File "/usr/local/lib/python3.6/site-packages/django/core/handlers/base.py", line 124, in _get_response
    response = wrapped_callback(request, *callback_args, **callback_kwargs)
  File "/usr/local/lib/python3.6/site-packages/django/views/generic/base.py", line 68, in view
    return self.dispatch(request, *args, **kwargs)
  File "/usr/local/lib/python3.6/site-packages/django/views/generic/base.py", line 88, in dispatch
    return handler(request, *args, **kwargs)
  File "/Users/zhang/Documents/Python/PESCM/ticket/ticket_view/ticket.py", line 325, in post
    ticket.done_time = tickt_form.handel_time
AttributeError: 'ChangeTimeForm' object has no attribute 'handel_time'
WARNING 2019-03-06 10:31:56,802 log Not Found: /favicon.ico
WARNING 2019-03-06 10:31:56,804 log Not Found: /
WARNING 2019-03-06 10:32:05,220 log Not Found: /
WARNING 2019-03-06 10:32:05,229 log Not Found: /favicon.ico
WARNING 2019-03-06 10:32:06,933 log Not Found: /api
WARNING 2019-03-06 10:32:07,001 log Not Found: /favicon.ico
WARNING 2019-03-06 10:32:18,551 log Not Found: /favicon.ico
WARNING 2019-03-06 10:32:42,014 log Not Found: /favicon.ico
ERROR 2019-03-06 10:34:43,229 log Internal Server Error: /api/ticket/detail/
Traceback (most recent call last):
  File "/usr/local/lib/python3.6/site-packages/django/template/smartif.py", line 175, in translate_token
    op = OPERATORS[token]
KeyError: '|'

During handling of the above exception, another exception occurred:

Traceback (most recent call last):
  File "/usr/local/lib/python3.6/site-packages/django/core/handlers/exception.py", line 34, in inner
    response = get_response(request)
  File "/usr/local/lib/python3.6/site-packages/django/core/handlers/base.py", line 126, in _get_response
    response = self.process_exception_by_middleware(e, request)
  File "/usr/local/lib/python3.6/site-packages/django/core/handlers/base.py", line 124, in _get_response
    response = wrapped_callback(request, *callback_args, **callback_kwargs)
  File "/usr/local/lib/python3.6/site-packages/django/views/generic/base.py", line 68, in view
    return self.dispatch(request, *args, **kwargs)
  File "/usr/local/lib/python3.6/site-packages/django/views/generic/base.py", line 88, in dispatch
    return handler(request, *args, **kwargs)
  File "/Users/zhang/Documents/Python/PESCM/ticket/ticket_view/ticket.py", line 282, in get
    'user': user
  File "/usr/local/lib/python3.6/site-packages/django/shortcuts.py", line 36, in render
    content = loader.render_to_string(template_name, context, request, using=using)
  File "/usr/local/lib/python3.6/site-packages/django/template/loader.py", line 61, in render_to_string
    template = get_template(template_name, using=using)
  File "/usr/local/lib/python3.6/site-packages/django/template/loader.py", line 15, in get_template
    return engine.get_template(template_name)
  File "/usr/local/lib/python3.6/site-packages/django/template/backends/django.py", line 34, in get_template
    return Template(self.engine.get_template(template_name), self)
  File "/usr/local/lib/python3.6/site-packages/django/template/engine.py", line 144, in get_template
    template, origin = self.find_template(template_name)
  File "/usr/local/lib/python3.6/site-packages/django/template/engine.py", line 126, in find_template
    template = loader.get_template(name, skip=skip)
  File "/usr/local/lib/python3.6/site-packages/django/template/loaders/base.py", line 30, in get_template
    contents, origin, origin.template_name, self.engine,
  File "/usr/local/lib/python3.6/site-packages/django/template/base.py", line 156, in __init__
    self.nodelist = self.compile_nodelist()
  File "/usr/local/lib/python3.6/site-packages/django/template/base.py", line 194, in compile_nodelist
    return parser.parse()
  File "/usr/local/lib/python3.6/site-packages/django/template/base.py", line 478, in parse
    raise self.error(token, e)
  File "/usr/local/lib/python3.6/site-packages/django/template/base.py", line 476, in parse
    compiled_result = compile_func(self, token)
  File "/usr/local/lib/python3.6/site-packages/django/template/loader_tags.py", line 266, in do_extends
    nodelist = parser.parse()
  File "/usr/local/lib/python3.6/site-packages/django/template/base.py", line 478, in parse
    raise self.error(token, e)
  File "/usr/local/lib/python3.6/site-packages/django/template/base.py", line 476, in parse
    compiled_result = compile_func(self, token)
  File "/usr/local/lib/python3.6/site-packages/django/template/loader_tags.py", line 209, in do_block
    nodelist = parser.parse(('endblock',))
  File "/usr/local/lib/python3.6/site-packages/django/template/base.py", line 478, in parse
    raise self.error(token, e)
  File "/usr/local/lib/python3.6/site-packages/django/template/base.py", line 476, in parse
    compiled_result = compile_func(self, token)
  File "/usr/local/lib/python3.6/site-packages/django/template/defaulttags.py", line 810, in do_for
    nodelist_loop = parser.parse(('empty', 'endfor',))
  File "/usr/local/lib/python3.6/site-packages/django/template/base.py", line 478, in parse
    raise self.error(token, e)
  File "/usr/local/lib/python3.6/site-packages/django/template/base.py", line 476, in parse
    compiled_result = compile_func(self, token)
  File "/usr/local/lib/python3.6/site-packages/django/template/defaulttags.py", line 950, in do_if
    condition = TemplateIfParser(parser, bits).parse()
  File "/usr/local/lib/python3.6/site-packages/django/template/defaulttags.py", line 883, in __init__
    super().__init__(*args, **kwargs)
  File "/usr/local/lib/python3.6/site-packages/django/template/smartif.py", line 166, in __init__
    mapped_tokens.append(self.translate_token(token))
  File "/usr/local/lib/python3.6/site-packages/django/template/smartif.py", line 177, in translate_token
    return self.create_var(token)
  File "/usr/local/lib/python3.6/site-packages/django/template/defaulttags.py", line 886, in create_var
    return TemplateLiteral(self.template_parser.compile_filter(value), value)
  File "/usr/local/lib/python3.6/site-packages/django/template/base.py", line 563, in compile_filter
    return FilterExpression(token, self)
  File "/usr/local/lib/python3.6/site-packages/django/template/base.py", line 663, in __init__
    "from '%s'" % (token[upto:], token))
django.template.exceptions.TemplateSyntaxError: Could not parse the remainder: '|' from '|'
ERROR 2019-03-06 10:34:57,461 log Internal Server Error: /api/ticket/detail/
Traceback (most recent call last):
  File "/usr/local/lib/python3.6/site-packages/django/template/smartif.py", line 175, in translate_token
    op = OPERATORS[token]
KeyError: '||'

During handling of the above exception, another exception occurred:

Traceback (most recent call last):
  File "/usr/local/lib/python3.6/site-packages/django/core/handlers/exception.py", line 34, in inner
    response = get_response(request)
  File "/usr/local/lib/python3.6/site-packages/django/core/handlers/base.py", line 126, in _get_response
    response = self.process_exception_by_middleware(e, request)
  File "/usr/local/lib/python3.6/site-packages/django/core/handlers/base.py", line 124, in _get_response
    response = wrapped_callback(request, *callback_args, **callback_kwargs)
  File "/usr/local/lib/python3.6/site-packages/django/views/generic/base.py", line 68, in view
    return self.dispatch(request, *args, **kwargs)
  File "/usr/local/lib/python3.6/site-packages/django/views/generic/base.py", line 88, in dispatch
    return handler(request, *args, **kwargs)
  File "/Users/zhang/Documents/Python/PESCM/ticket/ticket_view/ticket.py", line 282, in get
    'user': user
  File "/usr/local/lib/python3.6/site-packages/django/shortcuts.py", line 36, in render
    content = loader.render_to_string(template_name, context, request, using=using)
  File "/usr/local/lib/python3.6/site-packages/django/template/loader.py", line 61, in render_to_string
    template = get_template(template_name, using=using)
  File "/usr/local/lib/python3.6/site-packages/django/template/loader.py", line 15, in get_template
    return engine.get_template(template_name)
  File "/usr/local/lib/python3.6/site-packages/django/template/backends/django.py", line 34, in get_template
    return Template(self.engine.get_template(template_name), self)
  File "/usr/local/lib/python3.6/site-packages/django/template/engine.py", line 144, in get_template
    template, origin = self.find_template(template_name)
  File "/usr/local/lib/python3.6/site-packages/django/template/engine.py", line 126, in find_template
    template = loader.get_template(name, skip=skip)
  File "/usr/local/lib/python3.6/site-packages/django/template/loaders/base.py", line 30, in get_template
    contents, origin, origin.template_name, self.engine,
  File "/usr/local/lib/python3.6/site-packages/django/template/base.py", line 156, in __init__
    self.nodelist = self.compile_nodelist()
  File "/usr/local/lib/python3.6/site-packages/django/template/base.py", line 194, in compile_nodelist
    return parser.parse()
  File "/usr/local/lib/python3.6/site-packages/django/template/base.py", line 478, in parse
    raise self.error(token, e)
  File "/usr/local/lib/python3.6/site-packages/django/template/base.py", line 476, in parse
    compiled_result = compile_func(self, token)
  File "/usr/local/lib/python3.6/site-packages/django/template/loader_tags.py", line 266, in do_extends
    nodelist = parser.parse()
  File "/usr/local/lib/python3.6/site-packages/django/template/base.py", line 478, in parse
    raise self.error(token, e)
  File "/usr/local/lib/python3.6/site-packages/django/template/base.py", line 476, in parse
    compiled_result = compile_func(self, token)
  File "/usr/local/lib/python3.6/site-packages/django/template/loader_tags.py", line 209, in do_block
    nodelist = parser.parse(('endblock',))
  File "/usr/local/lib/python3.6/site-packages/django/template/base.py", line 478, in parse
    raise self.error(token, e)
  File "/usr/local/lib/python3.6/site-packages/django/template/base.py", line 476, in parse
    compiled_result = compile_func(self, token)
  File "/usr/local/lib/python3.6/site-packages/django/template/defaulttags.py", line 810, in do_for
    nodelist_loop = parser.parse(('empty', 'endfor',))
  File "/usr/local/lib/python3.6/site-packages/django/template/base.py", line 478, in parse
    raise self.error(token, e)
  File "/usr/local/lib/python3.6/site-packages/django/template/base.py", line 476, in parse
    compiled_result = compile_func(self, token)
  File "/usr/local/lib/python3.6/site-packages/django/template/defaulttags.py", line 950, in do_if
    condition = TemplateIfParser(parser, bits).parse()
  File "/usr/local/lib/python3.6/site-packages/django/template/defaulttags.py", line 883, in __init__
    super().__init__(*args, **kwargs)
  File "/usr/local/lib/python3.6/site-packages/django/template/smartif.py", line 166, in __init__
    mapped_tokens.append(self.translate_token(token))
  File "/usr/local/lib/python3.6/site-packages/django/template/smartif.py", line 177, in translate_token
    return self.create_var(token)
  File "/usr/local/lib/python3.6/site-packages/django/template/defaulttags.py", line 886, in create_var
    return TemplateLiteral(self.template_parser.compile_filter(value), value)
  File "/usr/local/lib/python3.6/site-packages/django/template/base.py", line 563, in compile_filter
    return FilterExpression(token, self)
  File "/usr/local/lib/python3.6/site-packages/django/template/base.py", line 663, in __init__
    "from '%s'" % (token[upto:], token))
django.template.exceptions.TemplateSyntaxError: Could not parse the remainder: '||' from '||'
WARNING 2019-03-06 10:36:06,123 log Not Found: /favicon.ico
WARNING 2019-03-06 10:36:17,872 log Not Found: /favicon.ico
WARNING 2019-03-06 10:39:34,977 log Not Found: /favicon.ico
WARNING 2019-03-06 10:48:42,227 log Not Found: /favicon.ico
WARNING 2019-03-06 10:48:49,400 log Not Found: /favicon.ico
WARNING 2019-03-06 10:49:10,288 log Not Found: /favicon.ico
WARNING 2019-03-06 10:49:12,371 log Not Found: /favicon.ico
WARNING 2019-03-06 10:49:13,520 log Not Found: /favicon.ico
WARNING 2019-03-06 10:51:01,477 log Not Found: /favicon.ico
WARNING 2019-03-06 10:56:01,288 log Not Found: /favicon.ico
WARNING 2019-03-06 10:56:09,879 log Not Found: /favicon.ico
WARNING 2019-03-06 10:56:17,677 log Not Found: /favicon.ico
WARNING 2019-03-06 10:56:24,183 log Not Found: /favicon.ico
WARNING 2019-03-06 10:58:50,706 log Not Found: /favicon.ico
WARNING 2019-03-06 10:59:17,442 log Not Found: /favicon.ico
WARNING 2019-03-06 11:00:24,882 log Not Found: /favicon.ico
WARNING 2019-03-06 11:01:54,387 log Not Found: /favicon.ico
WARNING 2019-03-06 11:06:34,164 log Not Found: /favicon.ico
WARNING 2019-03-06 11:19:00,149 log Not Found: /favicon.ico
WARNING 2019-03-06 11:19:08,936 log Not Found: /favicon.ico
WARNING 2019-03-06 11:19:32,508 log Not Found: /favicon.ico
WARNING 2019-03-06 11:22:30,403 log Not Found: /favicon.ico
WARNING 2019-03-06 11:22:46,758 log Not Found: /favicon.ico
WARNING 2019-03-06 11:22:52,326 log Not Found: /favicon.ico
WARNING 2019-03-06 11:22:56,267 log Not Found: /favicon.ico
WARNING 2019-03-06 11:23:21,041 log Not Found: /favicon.ico
WARNING 2019-03-06 13:13:33,649 log Not Found: /favicon.ico
WARNING 2019-03-06 13:13:37,841 log Not Found: /favicon.ico
WARNING 2019-03-06 13:14:29,108 log Not Found: /favicon.ico
WARNING 2019-03-06 13:23:23,865 log Not Found: /favicon.ico
WARNING 2019-03-06 13:30:01,856 log Not Found: /favicon.ico
WARNING 2019-03-06 13:30:59,889 log Not Found: /favicon.ico
WARNING 2019-03-06 13:31:23,410 log Not Found: /favicon.ico
WARNING 2019-03-06 13:37:01,061 log Not Found: /favicon.ico
WARNING 2019-03-06 13:46:18,030 log Not Found: /favicon.ico
