ERROR 2019-01-24 17:40:34,616 log Internal Server Error: /api/ticket/create/
Traceback (most recent call last):
  File "/usr/local/python3/lib/python3.6/site-packages/django/core/handlers/exception.py", line 34, in inner
    response = get_response(request)
  File "/usr/local/python3/lib/python3.6/site-packages/django/core/handlers/base.py", line 126, in _get_response
    response = self.process_exception_by_middleware(e, request)
  File "/usr/local/python3/lib/python3.6/site-packages/django/core/handlers/base.py", line 124, in _get_response
    response = wrapped_callback(request, *callback_args, **callback_kwargs)
  File "/usr/local/python3/lib/python3.6/site-packages/django/views/generic/base.py", line 68, in view
    return self.dispatch(request, *args, **kwargs)
  File "/usr/local/python3/lib/python3.6/site-packages/django/views/generic/base.py", line 88, in dispatch
    return handler(request, *args, **kwargs)
  File "./ticket/ticket_view/ticket.py", line 92, in post
    sender_email_ticket(ticket)
  File "./ticket/ticket_view/send_email.py", line 13, in sender_email_ticket
    senderuser, fail_silently=False)
  File "/usr/local/python3/lib/python3.6/site-packages/django/core/mail/__init__.py", line 60, in send_mail
    return mail.send()
  File "/usr/local/python3/lib/python3.6/site-packages/django/core/mail/message.py", line 291, in send
    return self.get_connection(fail_silently).send_messages([self])
  File "/usr/local/python3/lib/python3.6/site-packages/django/core/mail/backends/smtp.py", line 110, in send_messages
    sent = self._send(message)
  File "/usr/local/python3/lib/python3.6/site-packages/django/core/mail/backends/smtp.py", line 126, in _send
    self.connection.sendmail(from_email, recipients, message.as_bytes(linesep='\r\n'))
  File "/usr/local/python3/lib/python3.6/smtplib.py", line 888, in sendmail
    raise SMTPDataError(code, resp)
smtplib.SMTPDataError: (554, b'DT:SPM 163 smtp14,EsCowABXoN8SiElcRiPGCw--.30064S2 1548322834,please see http://mail.163.com/help/help_spam_16.htm?ip=219.141.250.88&hostid=smtp14&time=1548322834')
WARNING 2019-01-25 09:03:04,029 log Not Found: /favicon.ico
WARNING 2019-01-25 09:03:07,754 log Not Found: /favicon.ico
WARNING 2019-01-25 09:03:11,908 log Not Found: /favicon.ico
ERROR 2019-01-25 09:05:15,882 log Internal Server Error: /api/ticket/server/detail/
Traceback (most recent call last):
  File "/usr/local/lib/python3.6/site-packages/django/core/handlers/exception.py", line 34, in inner
    response = get_response(request)
  File "/usr/local/lib/python3.6/site-packages/django/core/handlers/base.py", line 126, in _get_response
    response = self.process_exception_by_middleware(e, request)
  File "/usr/local/lib/python3.6/site-packages/django/core/handlers/base.py", line 124, in _get_response
    response = wrapped_callback(request, *callback_args, **callback_kwargs)
  File "/usr/local/lib/python3.6/site-packages/django/views/generic/base.py", line 68, in view
    return self.dispatch(request, *args, **kwargs)
  File "/usr/local/lib/python3.6/site-packages/django/views/generic/base.py", line 88, in dispatch
    return handler(request, *args, **kwargs)
  File "/Users/zhang/Documents/Python/PESCM/ticket/ticket_view/ticket.py", line 367, in post
    ticket.save()
  File "/usr/local/lib/python3.6/site-packages/django/db/models/base.py", line 718, in save
    force_update=force_update, update_fields=update_fields)
  File "/usr/local/lib/python3.6/site-packages/django/db/models/base.py", line 748, in save_base
    updated = self._save_table(raw, cls, force_insert, force_update, using, update_fields)
  File "/usr/local/lib/python3.6/site-packages/django/db/models/base.py", line 812, in _save_table
    forced_update)
  File "/usr/local/lib/python3.6/site-packages/django/db/models/base.py", line 861, in _do_update
    return filtered._update(values) > 0
  File "/usr/local/lib/python3.6/site-packages/django/db/models/query.py", line 712, in _update
    return query.get_compiler(self.db).execute_sql(CURSOR)
  File "/usr/local/lib/python3.6/site-packages/django/db/models/sql/compiler.py", line 1383, in execute_sql
    cursor = super().execute_sql(result_type)
  File "/usr/local/lib/python3.6/site-packages/django/db/models/sql/compiler.py", line 1052, in execute_sql
    sql, params = self.as_sql()
  File "/usr/local/lib/python3.6/site-packages/django/db/models/sql/compiler.py", line 1349, in as_sql
    val = field.get_db_prep_save(val, connection=self.connection)
  File "/usr/local/lib/python3.6/site-packages/django/db/models/fields/__init__.py", line 790, in get_db_prep_save
    return self.get_db_prep_value(value, connection=connection, prepared=False)
  File "/usr/local/lib/python3.6/site-packages/django/db/models/fields/__init__.py", line 1273, in get_db_prep_value
    value = self.get_prep_value(value)
  File "/usr/local/lib/python3.6/site-packages/django/db/models/fields/__init__.py", line 1268, in get_prep_value
    return self.to_python(value)
  File "/usr/local/lib/python3.6/site-packages/django/db/models/fields/__init__.py", line 1230, in to_python
    parsed = parse_date(value)
  File "/usr/local/lib/python3.6/site-packages/django/utils/dateparse.py", line 74, in parse_date
    match = date_re.match(value)
TypeError: expected string or bytes-like object
ERROR 2019-01-25 09:07:52,317 log Internal Server Error: /api/ticket/server/detail/
Traceback (most recent call last):
  File "/usr/local/lib/python3.6/site-packages/django/core/handlers/exception.py", line 34, in inner
    response = get_response(request)
  File "/usr/local/lib/python3.6/site-packages/django/core/handlers/base.py", line 126, in _get_response
    response = self.process_exception_by_middleware(e, request)
  File "/usr/local/lib/python3.6/site-packages/django/core/handlers/base.py", line 124, in _get_response
    response = wrapped_callback(request, *callback_args, **callback_kwargs)
  File "/usr/local/lib/python3.6/site-packages/django/views/generic/base.py", line 68, in view
    return self.dispatch(request, *args, **kwargs)
  File "/usr/local/lib/python3.6/site-packages/django/views/generic/base.py", line 88, in dispatch
    return handler(request, *args, **kwargs)
  File "/Users/zhang/Documents/Python/PESCM/ticket/ticket_view/ticket.py", line 367, in post
    ticket.save()
  File "/usr/local/lib/python3.6/site-packages/django/db/models/base.py", line 718, in save
    force_update=force_update, update_fields=update_fields)
  File "/usr/local/lib/python3.6/site-packages/django/db/models/base.py", line 748, in save_base
    updated = self._save_table(raw, cls, force_insert, force_update, using, update_fields)
  File "/usr/local/lib/python3.6/site-packages/django/db/models/base.py", line 812, in _save_table
    forced_update)
  File "/usr/local/lib/python3.6/site-packages/django/db/models/base.py", line 861, in _do_update
    return filtered._update(values) > 0
  File "/usr/local/lib/python3.6/site-packages/django/db/models/query.py", line 712, in _update
    return query.get_compiler(self.db).execute_sql(CURSOR)
  File "/usr/local/lib/python3.6/site-packages/django/db/models/sql/compiler.py", line 1383, in execute_sql
    cursor = super().execute_sql(result_type)
  File "/usr/local/lib/python3.6/site-packages/django/db/models/sql/compiler.py", line 1052, in execute_sql
    sql, params = self.as_sql()
  File "/usr/local/lib/python3.6/site-packages/django/db/models/sql/compiler.py", line 1349, in as_sql
    val = field.get_db_prep_save(val, connection=self.connection)
  File "/usr/local/lib/python3.6/site-packages/django/db/models/fields/__init__.py", line 790, in get_db_prep_save
    return self.get_db_prep_value(value, connection=connection, prepared=False)
  File "/usr/local/lib/python3.6/site-packages/django/db/models/fields/__init__.py", line 1273, in get_db_prep_value
    value = self.get_prep_value(value)
  File "/usr/local/lib/python3.6/site-packages/django/db/models/fields/__init__.py", line 1268, in get_prep_value
    return self.to_python(value)
  File "/usr/local/lib/python3.6/site-packages/django/db/models/fields/__init__.py", line 1230, in to_python
    parsed = parse_date(value)
  File "/usr/local/lib/python3.6/site-packages/django/utils/dateparse.py", line 74, in parse_date
    match = date_re.match(value)
TypeError: expected string or bytes-like object
WARNING 2019-01-25 09:32:13,814 log Not Found: /favicon.ico
WARNING 2019-01-25 09:32:17,316 log Not Found: /favicon.ico
WARNING 2019-01-25 09:52:41,775 log Not Found: /favicon.ico
WARNING 2019-01-25 10:18:16,348 log Not Found: /favicon.ico
<<<<<<< HEAD
WARNING 2019-01-25 14:30:59,148 log Not Found: /uploads/image/default.png
=======
WARNING 2019-01-29 12:23:40,736 log Not Found: /
ERROR 2019-01-29 12:23:56,425 log Internal Server Error: /api/ticket/send/
Traceback (most recent call last):
  File "/usr/local/lib/python3.6/site-packages/django/core/handlers/exception.py", line 34, in inner
    response = get_response(request)
  File "/usr/local/lib/python3.6/site-packages/django/core/handlers/base.py", line 126, in _get_response
    response = self.process_exception_by_middleware(e, request)
  File "/usr/local/lib/python3.6/site-packages/django/core/handlers/base.py", line 124, in _get_response
    response = wrapped_callback(request, *callback_args, **callback_kwargs)
TypeError: sender() takes 0 positional arguments but 1 was given
ERROR 2019-01-29 12:24:24,047 log Internal Server Error: /api/ticket/send/
Traceback (most recent call last):
  File "/usr/local/lib/python3.6/site-packages/django/core/handlers/exception.py", line 34, in inner
    response = get_response(request)
  File "/usr/local/lib/python3.6/site-packages/django/core/handlers/base.py", line 126, in _get_response
    response = self.process_exception_by_middleware(e, request)
  File "/usr/local/lib/python3.6/site-packages/django/core/handlers/base.py", line 124, in _get_response
    response = wrapped_callback(request, *callback_args, **callback_kwargs)
TypeError: sender() takes 0 positional arguments but 1 was given
ERROR 2019-01-29 12:24:27,369 log Internal Server Error: /api/ticket/send/
Traceback (most recent call last):
  File "/usr/local/lib/python3.6/site-packages/django/core/handlers/exception.py", line 34, in inner
    response = get_response(request)
  File "/usr/local/lib/python3.6/site-packages/django/core/handlers/base.py", line 126, in _get_response
    response = self.process_exception_by_middleware(e, request)
  File "/usr/local/lib/python3.6/site-packages/django/core/handlers/base.py", line 124, in _get_response
    response = wrapped_callback(request, *callback_args, **callback_kwargs)
TypeError: sender() takes 0 positional arguments but 1 was given
ERROR 2019-01-29 12:24:54,184 log Internal Server Error: /api/ticket/send/
Traceback (most recent call last):
  File "/usr/local/lib/python3.6/site-packages/django/core/handlers/exception.py", line 34, in inner
    response = get_response(request)
  File "/usr/local/lib/python3.6/site-packages/django/core/handlers/base.py", line 137, in _get_response
    "returned None instead." % (callback.__module__, view_name)
ValueError: The view ticket.ticket_view.send_email.sender didn't return an HttpResponse object. It returned None instead.
>>>>>>> d396ce8204713088046b72fdca82c8f88bc08ab3
ERROR 2019-01-29 12:45:25,142 log Internal Server Error: /api/ticket/send/
Traceback (most recent call last):
  File "/usr/local/python3/lib/python3.6/site-packages/django/core/handlers/exception.py", line 34, in inner
    response = get_response(request)
  File "/usr/local/python3/lib/python3.6/site-packages/django/core/handlers/base.py", line 126, in _get_response
    response = self.process_exception_by_middleware(e, request)
  File "/usr/local/python3/lib/python3.6/site-packages/django/core/handlers/base.py", line 124, in _get_response
    response = wrapped_callback(request, *callback_args, **callback_kwargs)
TypeError: sender_email() takes 0 positional arguments but 1 was given
ERROR 2019-01-29 12:48:51,839 log Internal Server Error: /api/ticket/send/
Traceback (most recent call last):
  File "/usr/local/python3/lib/python3.6/site-packages/django/core/handlers/exception.py", line 34, in inner
    response = get_response(request)
  File "/usr/local/python3/lib/python3.6/site-packages/django/core/handlers/base.py", line 126, in _get_response
    response = self.process_exception_by_middleware(e, request)
  File "/usr/local/python3/lib/python3.6/site-packages/django/core/handlers/base.py", line 124, in _get_response
    response = wrapped_callback(request, *callback_args, **callback_kwargs)
TypeError: sender_email() takes 0 positional arguments but 1 was given
