ERROR 2019-01-24 17:40:34,616 log Internal Server Error: /api/ticket/create/
Traceback (most recent call last):
  File "/usr/local/python3/lib/python3.6/site-packages/django/core/handlers/exception.py", line 34, in inner
    response = get_response(request)
  File "/usr/local/python3/lib/python3.6/site-packages/django/core/handlers/base.py", line 126, in _get_response
    response = self.process_exception_by_middleware(e, request)
  File "/usr/local/python3/lib/python3.6/site-packages/django/core/handlers/base.py", line 124, in _get_response
    response = wrapped_callback(request, *callback_args, **callback_kwargs)
  File "/usr/local/python3/lib/python3.6/site-packages/django/views/generic/base.py", line 68, in view
    return self.dispatch(request, *args, **kwargs)
  File "/usr/local/python3/lib/python3.6/site-packages/django/views/generic/base.py", line 88, in dispatch
    return handler(request, *args, **kwargs)
  File "./ticket/ticket_view/ticket.py", line 92, in post
    sender_email_ticket(ticket)
  File "./ticket/ticket_view/send_email.py", line 13, in sender_email_ticket
    senderuser, fail_silently=False)
  File "/usr/local/python3/lib/python3.6/site-packages/django/core/mail/__init__.py", line 60, in send_mail
    return mail.send()
  File "/usr/local/python3/lib/python3.6/site-packages/django/core/mail/message.py", line 291, in send
    return self.get_connection(fail_silently).send_messages([self])
  File "/usr/local/python3/lib/python3.6/site-packages/django/core/mail/backends/smtp.py", line 110, in send_messages
    sent = self._send(message)
  File "/usr/local/python3/lib/python3.6/site-packages/django/core/mail/backends/smtp.py", line 126, in _send
    self.connection.sendmail(from_email, recipients, message.as_bytes(linesep='\r\n'))
  File "/usr/local/python3/lib/python3.6/smtplib.py", line 888, in sendmail
    raise SMTPDataError(code, resp)
smtplib.SMTPDataError: (554, b'DT:SPM 163 smtp14,EsCowABXoN8SiElcRiPGCw--.30064S2 1548322834,please see http://mail.163.com/help/help_spam_16.htm?ip=219.141.250.88&hostid=smtp14&time=1548322834')
WARNING 2019-01-25 09:03:04,029 log Not Found: /favicon.ico
WARNING 2019-01-25 09:03:07,754 log Not Found: /favicon.ico
WARNING 2019-01-25 09:03:11,908 log Not Found: /favicon.ico
ERROR 2019-01-25 09:05:15,882 log Internal Server Error: /api/ticket/server/detail/
Traceback (most recent call last):
  File "/usr/local/lib/python3.6/site-packages/django/core/handlers/exception.py", line 34, in inner
    response = get_response(request)
  File "/usr/local/lib/python3.6/site-packages/django/core/handlers/base.py", line 126, in _get_response
    response = self.process_exception_by_middleware(e, request)
  File "/usr/local/lib/python3.6/site-packages/django/core/handlers/base.py", line 124, in _get_response
    response = wrapped_callback(request, *callback_args, **callback_kwargs)
  File "/usr/local/lib/python3.6/site-packages/django/views/generic/base.py", line 68, in view
    return self.dispatch(request, *args, **kwargs)
  File "/usr/local/lib/python3.6/site-packages/django/views/generic/base.py", line 88, in dispatch
    return handler(request, *args, **kwargs)
  File "/Users/zhang/Documents/Python/PESCM/ticket/ticket_view/ticket.py", line 367, in post
    ticket.save()
  File "/usr/local/lib/python3.6/site-packages/django/db/models/base.py", line 718, in save
    force_update=force_update, update_fields=update_fields)
  File "/usr/local/lib/python3.6/site-packages/django/db/models/base.py", line 748, in save_base
    updated = self._save_table(raw, cls, force_insert, force_update, using, update_fields)
  File "/usr/local/lib/python3.6/site-packages/django/db/models/base.py", line 812, in _save_table
    forced_update)
  File "/usr/local/lib/python3.6/site-packages/django/db/models/base.py", line 861, in _do_update
    return filtered._update(values) > 0
  File "/usr/local/lib/python3.6/site-packages/django/db/models/query.py", line 712, in _update
    return query.get_compiler(self.db).execute_sql(CURSOR)
  File "/usr/local/lib/python3.6/site-packages/django/db/models/sql/compiler.py", line 1383, in execute_sql
    cursor = super().execute_sql(result_type)
  File "/usr/local/lib/python3.6/site-packages/django/db/models/sql/compiler.py", line 1052, in execute_sql
    sql, params = self.as_sql()
  File "/usr/local/lib/python3.6/site-packages/django/db/models/sql/compiler.py", line 1349, in as_sql
    val = field.get_db_prep_save(val, connection=self.connection)
  File "/usr/local/lib/python3.6/site-packages/django/db/models/fields/__init__.py", line 790, in get_db_prep_save
    return self.get_db_prep_value(value, connection=connection, prepared=False)
  File "/usr/local/lib/python3.6/site-packages/django/db/models/fields/__init__.py", line 1273, in get_db_prep_value
    value = self.get_prep_value(value)
  File "/usr/local/lib/python3.6/site-packages/django/db/models/fields/__init__.py", line 1268, in get_prep_value
    return self.to_python(value)
  File "/usr/local/lib/python3.6/site-packages/django/db/models/fields/__init__.py", line 1230, in to_python
    parsed = parse_date(value)
  File "/usr/local/lib/python3.6/site-packages/django/utils/dateparse.py", line 74, in parse_date
    match = date_re.match(value)
TypeError: expected string or bytes-like object
ERROR 2019-01-25 09:07:52,317 log Internal Server Error: /api/ticket/server/detail/
Traceback (most recent call last):
  File "/usr/local/lib/python3.6/site-packages/django/core/handlers/exception.py", line 34, in inner
    response = get_response(request)
  File "/usr/local/lib/python3.6/site-packages/django/core/handlers/base.py", line 126, in _get_response
    response = self.process_exception_by_middleware(e, request)
  File "/usr/local/lib/python3.6/site-packages/django/core/handlers/base.py", line 124, in _get_response
    response = wrapped_callback(request, *callback_args, **callback_kwargs)
  File "/usr/local/lib/python3.6/site-packages/django/views/generic/base.py", line 68, in view
    return self.dispatch(request, *args, **kwargs)
  File "/usr/local/lib/python3.6/site-packages/django/views/generic/base.py", line 88, in dispatch
    return handler(request, *args, **kwargs)
  File "/Users/zhang/Documents/Python/PESCM/ticket/ticket_view/ticket.py", line 367, in post
    ticket.save()
  File "/usr/local/lib/python3.6/site-packages/django/db/models/base.py", line 718, in save
    force_update=force_update, update_fields=update_fields)
  File "/usr/local/lib/python3.6/site-packages/django/db/models/base.py", line 748, in save_base
    updated = self._save_table(raw, cls, force_insert, force_update, using, update_fields)
  File "/usr/local/lib/python3.6/site-packages/django/db/models/base.py", line 812, in _save_table
    forced_update)
  File "/usr/local/lib/python3.6/site-packages/django/db/models/base.py", line 861, in _do_update
    return filtered._update(values) > 0
  File "/usr/local/lib/python3.6/site-packages/django/db/models/query.py", line 712, in _update
    return query.get_compiler(self.db).execute_sql(CURSOR)
  File "/usr/local/lib/python3.6/site-packages/django/db/models/sql/compiler.py", line 1383, in execute_sql
    cursor = super().execute_sql(result_type)
  File "/usr/local/lib/python3.6/site-packages/django/db/models/sql/compiler.py", line 1052, in execute_sql
    sql, params = self.as_sql()
  File "/usr/local/lib/python3.6/site-packages/django/db/models/sql/compiler.py", line 1349, in as_sql
    val = field.get_db_prep_save(val, connection=self.connection)
  File "/usr/local/lib/python3.6/site-packages/django/db/models/fields/__init__.py", line 790, in get_db_prep_save
    return self.get_db_prep_value(value, connection=connection, prepared=False)
  File "/usr/local/lib/python3.6/site-packages/django/db/models/fields/__init__.py", line 1273, in get_db_prep_value
    value = self.get_prep_value(value)
  File "/usr/local/lib/python3.6/site-packages/django/db/models/fields/__init__.py", line 1268, in get_prep_value
    return self.to_python(value)
  File "/usr/local/lib/python3.6/site-packages/django/db/models/fields/__init__.py", line 1230, in to_python
    parsed = parse_date(value)
  File "/usr/local/lib/python3.6/site-packages/django/utils/dateparse.py", line 74, in parse_date
    match = date_re.match(value)
TypeError: expected string or bytes-like object
WARNING 2019-01-25 09:32:13,814 log Not Found: /favicon.ico
WARNING 2019-01-25 09:32:17,316 log Not Found: /favicon.ico
WARNING 2019-01-25 09:52:41,775 log Not Found: /favicon.ico
WARNING 2019-01-25 10:18:16,348 log Not Found: /favicon.ico
<<<<<<< HEAD
WARNING 2019-01-25 14:30:59,148 log Not Found: /uploads/image/default.png
=======
WARNING 2019-01-29 12:23:40,736 log Not Found: /
ERROR 2019-01-29 12:23:56,425 log Internal Server Error: /api/ticket/send/
Traceback (most recent call last):
  File "/usr/local/lib/python3.6/site-packages/django/core/handlers/exception.py", line 34, in inner
    response = get_response(request)
  File "/usr/local/lib/python3.6/site-packages/django/core/handlers/base.py", line 126, in _get_response
    response = self.process_exception_by_middleware(e, request)
  File "/usr/local/lib/python3.6/site-packages/django/core/handlers/base.py", line 124, in _get_response
    response = wrapped_callback(request, *callback_args, **callback_kwargs)
TypeError: sender() takes 0 positional arguments but 1 was given
ERROR 2019-01-29 12:24:24,047 log Internal Server Error: /api/ticket/send/
Traceback (most recent call last):
  File "/usr/local/lib/python3.6/site-packages/django/core/handlers/exception.py", line 34, in inner
    response = get_response(request)
  File "/usr/local/lib/python3.6/site-packages/django/core/handlers/base.py", line 126, in _get_response
    response = self.process_exception_by_middleware(e, request)
  File "/usr/local/lib/python3.6/site-packages/django/core/handlers/base.py", line 124, in _get_response
    response = wrapped_callback(request, *callback_args, **callback_kwargs)
TypeError: sender() takes 0 positional arguments but 1 was given
ERROR 2019-01-29 12:24:27,369 log Internal Server Error: /api/ticket/send/
Traceback (most recent call last):
  File "/usr/local/lib/python3.6/site-packages/django/core/handlers/exception.py", line 34, in inner
    response = get_response(request)
  File "/usr/local/lib/python3.6/site-packages/django/core/handlers/base.py", line 126, in _get_response
    response = self.process_exception_by_middleware(e, request)
  File "/usr/local/lib/python3.6/site-packages/django/core/handlers/base.py", line 124, in _get_response
    response = wrapped_callback(request, *callback_args, **callback_kwargs)
TypeError: sender() takes 0 positional arguments but 1 was given
ERROR 2019-01-29 12:24:54,184 log Internal Server Error: /api/ticket/send/
Traceback (most recent call last):
  File "/usr/local/lib/python3.6/site-packages/django/core/handlers/exception.py", line 34, in inner
    response = get_response(request)
  File "/usr/local/lib/python3.6/site-packages/django/core/handlers/base.py", line 137, in _get_response
    "returned None instead." % (callback.__module__, view_name)
ValueError: The view ticket.ticket_view.send_email.sender didn't return an HttpResponse object. It returned None instead.
<<<<<<< HEAD
>>>>>>> d396ce8204713088046b72fdca82c8f88bc08ab3
ERROR 2019-01-29 12:45:25,142 log Internal Server Error: /api/ticket/send/
Traceback (most recent call last):
  File "/usr/local/python3/lib/python3.6/site-packages/django/core/handlers/exception.py", line 34, in inner
    response = get_response(request)
  File "/usr/local/python3/lib/python3.6/site-packages/django/core/handlers/base.py", line 126, in _get_response
    response = self.process_exception_by_middleware(e, request)
  File "/usr/local/python3/lib/python3.6/site-packages/django/core/handlers/base.py", line 124, in _get_response
    response = wrapped_callback(request, *callback_args, **callback_kwargs)
TypeError: sender_email() takes 0 positional arguments but 1 was given
ERROR 2019-01-29 12:48:51,839 log Internal Server Error: /api/ticket/send/
Traceback (most recent call last):
  File "/usr/local/python3/lib/python3.6/site-packages/django/core/handlers/exception.py", line 34, in inner
    response = get_response(request)
  File "/usr/local/python3/lib/python3.6/site-packages/django/core/handlers/base.py", line 126, in _get_response
    response = self.process_exception_by_middleware(e, request)
  File "/usr/local/python3/lib/python3.6/site-packages/django/core/handlers/base.py", line 124, in _get_response
    response = wrapped_callback(request, *callback_args, **callback_kwargs)
TypeError: sender_email() takes 0 positional arguments but 1 was given
ERROR 2019-01-29 12:51:32,998 log Internal Server Error: /api/ticket/send/
Traceback (most recent call last):
  File "/usr/local/python3/lib/python3.6/site-packages/django/core/handlers/exception.py", line 34, in inner
    response = get_response(request)
  File "/usr/local/python3/lib/python3.6/site-packages/django/core/handlers/base.py", line 126, in _get_response
    response = self.process_exception_by_middleware(e, request)
  File "/usr/local/python3/lib/python3.6/site-packages/django/core/handlers/base.py", line 124, in _get_response
    response = wrapped_callback(request, *callback_args, **callback_kwargs)
TypeError: sender_email() takes 0 positional arguments but 1 was given
ERROR 2019-01-29 12:51:39,069 log Internal Server Error: /api/ticket/send/
Traceback (most recent call last):
  File "/usr/local/python3/lib/python3.6/site-packages/django/core/handlers/exception.py", line 34, in inner
    response = get_response(request)
  File "/usr/local/python3/lib/python3.6/site-packages/django/core/handlers/base.py", line 126, in _get_response
    response = self.process_exception_by_middleware(e, request)
  File "/usr/local/python3/lib/python3.6/site-packages/django/core/handlers/base.py", line 124, in _get_response
    response = wrapped_callback(request, *callback_args, **callback_kwargs)
TypeError: sender_email() takes 0 positional arguments but 1 was given
ERROR 2019-01-29 12:51:42,798 log Internal Server Error: /api/ticket/send/
Traceback (most recent call last):
  File "/usr/local/python3/lib/python3.6/site-packages/django/core/handlers/exception.py", line 34, in inner
    response = get_response(request)
  File "/usr/local/python3/lib/python3.6/site-packages/django/core/handlers/base.py", line 126, in _get_response
    response = self.process_exception_by_middleware(e, request)
  File "/usr/local/python3/lib/python3.6/site-packages/django/core/handlers/base.py", line 124, in _get_response
    response = wrapped_callback(request, *callback_args, **callback_kwargs)
TypeError: sender_email() takes 0 positional arguments but 1 was given
ERROR 2019-01-29 12:54:50,594 log Internal Server Error: /api/ticket/send/
Traceback (most recent call last):
  File "/usr/local/python3/lib/python3.6/site-packages/django/core/handlers/exception.py", line 34, in inner
    response = get_response(request)
  File "/usr/local/python3/lib/python3.6/site-packages/django/core/handlers/base.py", line 126, in _get_response
    response = self.process_exception_by_middleware(e, request)
  File "/usr/local/python3/lib/python3.6/site-packages/django/core/handlers/base.py", line 124, in _get_response
    response = wrapped_callback(request, *callback_args, **callback_kwargs)
TypeError: sender_email() takes 0 positional arguments but 1 was given
ERROR 2019-01-29 12:54:59,081 log Internal Server Error: /api/ticket/send/
Traceback (most recent call last):
  File "/usr/local/python3/lib/python3.6/site-packages/django/core/handlers/exception.py", line 34, in inner
    response = get_response(request)
  File "/usr/local/python3/lib/python3.6/site-packages/django/core/handlers/base.py", line 126, in _get_response
    response = self.process_exception_by_middleware(e, request)
  File "/usr/local/python3/lib/python3.6/site-packages/django/core/handlers/base.py", line 124, in _get_response
    response = wrapped_callback(request, *callback_args, **callback_kwargs)
TypeError: sender_email() takes 0 positional arguments but 1 was given
ERROR 2019-01-29 12:55:01,089 log Internal Server Error: /api/ticket/send/
Traceback (most recent call last):
  File "/usr/local/python3/lib/python3.6/site-packages/django/core/handlers/exception.py", line 34, in inner
    response = get_response(request)
  File "/usr/local/python3/lib/python3.6/site-packages/django/core/handlers/base.py", line 126, in _get_response
    response = self.process_exception_by_middleware(e, request)
  File "/usr/local/python3/lib/python3.6/site-packages/django/core/handlers/base.py", line 124, in _get_response
    response = wrapped_callback(request, *callback_args, **callback_kwargs)
TypeError: sender_email() takes 0 positional arguments but 1 was given
ERROR 2019-01-29 12:55:24,007 log Internal Server Error: /api/ticket/send/
Traceback (most recent call last):
  File "/usr/local/python3/lib/python3.6/site-packages/django/core/handlers/exception.py", line 34, in inner
    response = get_response(request)
  File "/usr/local/python3/lib/python3.6/site-packages/django/core/handlers/base.py", line 126, in _get_response
    response = self.process_exception_by_middleware(e, request)
  File "/usr/local/python3/lib/python3.6/site-packages/django/core/handlers/base.py", line 124, in _get_response
    response = wrapped_callback(request, *callback_args, **callback_kwargs)
TypeError: sender_email() takes 0 positional arguments but 1 was given
ERROR 2019-01-29 12:56:39,075 log Internal Server Error: /api/ticket/send/
Traceback (most recent call last):
  File "/usr/local/python3/lib/python3.6/site-packages/django/core/handlers/exception.py", line 34, in inner
    response = get_response(request)
  File "/usr/local/python3/lib/python3.6/site-packages/django/core/handlers/base.py", line 126, in _get_response
    response = self.process_exception_by_middleware(e, request)
  File "/usr/local/python3/lib/python3.6/site-packages/django/core/handlers/base.py", line 124, in _get_response
=======
ERROR 2019-01-29 12:51:56,348 log Internal Server Error: /api/ticket/send/
Traceback (most recent call last):
  File "/usr/local/lib/python3.6/site-packages/django/core/handlers/exception.py", line 34, in inner
    response = get_response(request)
  File "/usr/local/lib/python3.6/site-packages/django/core/handlers/base.py", line 126, in _get_response
    response = self.process_exception_by_middleware(e, request)
  File "/usr/local/lib/python3.6/site-packages/django/core/handlers/base.py", line 124, in _get_response
>>>>>>> 74f7d6b35876dbe7f9369b5f391533f86f89038a
    response = wrapped_callback(request, *callback_args, **callback_kwargs)
TypeError: sender_email() takes 0 positional arguments but 1 was given
ERROR 2019-01-29 16:29:10,644 log Internal Server Error: /api/home/api/
Traceback (most recent call last):
  File "/usr/local/lib/python3.6/site-packages/django/core/handlers/exception.py", line 34, in inner
    response = get_response(request)
  File "/usr/local/lib/python3.6/site-packages/django/core/handlers/base.py", line 126, in _get_response
    response = self.process_exception_by_middleware(e, request)
  File "/usr/local/lib/python3.6/site-packages/django/core/handlers/base.py", line 124, in _get_response
    response = wrapped_callback(request, *callback_args, **callback_kwargs)
  File "/Users/zhang/Documents/Python/PESCM/ticket/ticket_view/account.py", line 80, in home_api
    for user in users:
NameError: name 'users' is not defined
ERROR 2019-01-29 16:30:26,255 log Internal Server Error: /api/home/api/
Traceback (most recent call last):
  File "/usr/local/lib/python3.6/site-packages/django/core/handlers/exception.py", line 34, in inner
    response = get_response(request)
  File "/usr/local/lib/python3.6/site-packages/django/core/handlers/base.py", line 126, in _get_response
    response = self.process_exception_by_middleware(e, request)
  File "/usr/local/lib/python3.6/site-packages/django/core/handlers/base.py", line 124, in _get_response
    response = wrapped_callback(request, *callback_args, **callback_kwargs)
  File "/Users/zhang/Documents/Python/PESCM/ticket/ticket_view/account.py", line 76, in home_api
    return JsonResponse({"actions_tickets": jsonData})
  File "/usr/local/lib/python3.6/site-packages/django/http/response.py", line 558, in __init__
    data = json.dumps(data, cls=encoder, **json_dumps_params)
  File "/usr/local/Cellar/python/3.6.5/Frameworks/Python.framework/Versions/3.6/lib/python3.6/json/__init__.py", line 238, in dumps
    **kw).encode(obj)
  File "/usr/local/Cellar/python/3.6.5/Frameworks/Python.framework/Versions/3.6/lib/python3.6/json/encoder.py", line 199, in encode
    chunks = self.iterencode(o, _one_shot=True)
  File "/usr/local/Cellar/python/3.6.5/Frameworks/Python.framework/Versions/3.6/lib/python3.6/json/encoder.py", line 257, in iterencode
    return _iterencode(o, 0)
  File "/usr/local/lib/python3.6/site-packages/django/core/serializers/json.py", line 104, in default
    return super().default(o)
  File "/usr/local/Cellar/python/3.6.5/Frameworks/Python.framework/Versions/3.6/lib/python3.6/json/encoder.py", line 180, in default
    o.__class__.__name__)
TypeError: Object of type 'FieldFile' is not JSON serializable
ERROR 2019-01-29 16:31:17,723 log Internal Server Error: /api/home/api/
Traceback (most recent call last):
  File "/usr/local/lib/python3.6/site-packages/django/core/handlers/exception.py", line 34, in inner
    response = get_response(request)
  File "/usr/local/lib/python3.6/site-packages/django/core/handlers/base.py", line 126, in _get_response
    response = self.process_exception_by_middleware(e, request)
  File "/usr/local/lib/python3.6/site-packages/django/core/handlers/base.py", line 124, in _get_response
    response = wrapped_callback(request, *callback_args, **callback_kwargs)
  File "/Users/zhang/Documents/Python/PESCM/ticket/ticket_view/account.py", line 76, in home_api
    return JsonResponse({"actions_tickets": jsonData})
  File "/usr/local/lib/python3.6/site-packages/django/http/response.py", line 558, in __init__
    data = json.dumps(data, cls=encoder, **json_dumps_params)
  File "/usr/local/Cellar/python/3.6.5/Frameworks/Python.framework/Versions/3.6/lib/python3.6/json/__init__.py", line 238, in dumps
    **kw).encode(obj)
  File "/usr/local/Cellar/python/3.6.5/Frameworks/Python.framework/Versions/3.6/lib/python3.6/json/encoder.py", line 199, in encode
    chunks = self.iterencode(o, _one_shot=True)
  File "/usr/local/Cellar/python/3.6.5/Frameworks/Python.framework/Versions/3.6/lib/python3.6/json/encoder.py", line 257, in iterencode
    return _iterencode(o, 0)
  File "/usr/local/lib/python3.6/site-packages/django/core/serializers/json.py", line 104, in default
    return super().default(o)
  File "/usr/local/Cellar/python/3.6.5/Frameworks/Python.framework/Versions/3.6/lib/python3.6/json/encoder.py", line 180, in default
    o.__class__.__name__)
TypeError: Object of type 'TicketConfim' is not JSON serializable
ERROR 2019-01-29 16:54:17,074 log Internal Server Error: /api/home/api/
Traceback (most recent call last):
  File "/usr/local/lib/python3.6/site-packages/django/core/handlers/exception.py", line 34, in inner
    response = get_response(request)
  File "/usr/local/lib/python3.6/site-packages/django/core/handlers/base.py", line 126, in _get_response
    response = self.process_exception_by_middleware(e, request)
  File "/usr/local/lib/python3.6/site-packages/django/core/handlers/base.py", line 124, in _get_response
    response = wrapped_callback(request, *callback_args, **callback_kwargs)
TypeError: home_api() missing 1 required positional argument: 'callback'
ERROR 2019-01-30 09:00:40,258 log Internal Server Error: /api/home/api/
Traceback (most recent call last):
  File "/usr/local/lib/python3.6/site-packages/django/core/handlers/exception.py", line 34, in inner
    response = get_response(request)
  File "/usr/local/lib/python3.6/site-packages/django/core/handlers/base.py", line 126, in _get_response
    response = self.process_exception_by_middleware(e, request)
  File "/usr/local/lib/python3.6/site-packages/django/core/handlers/base.py", line 124, in _get_response
    response = wrapped_callback(request, *callback_args, **callback_kwargs)
TypeError: home_api() missing 1 required positional argument: 'callback'
ERROR 2019-01-30 09:04:27,471 log Internal Server Error: /api/home/api/
Traceback (most recent call last):
  File "/usr/local/lib/python3.6/site-packages/django/core/handlers/exception.py", line 34, in inner
    response = get_response(request)
  File "/usr/local/lib/python3.6/site-packages/django/core/handlers/base.py", line 126, in _get_response
    response = self.process_exception_by_middleware(e, request)
  File "/usr/local/lib/python3.6/site-packages/django/core/handlers/base.py", line 124, in _get_response
    response = wrapped_callback(request, *callback_args, **callback_kwargs)
TypeError: home_api() missing 1 required positional argument: 'callback'
ERROR 2019-01-30 09:06:56,943 log Internal Server Error: /api/home/api/
Traceback (most recent call last):
  File "/usr/local/lib/python3.6/site-packages/django/core/handlers/exception.py", line 34, in inner
    response = get_response(request)
  File "/usr/local/lib/python3.6/site-packages/django/core/handlers/base.py", line 126, in _get_response
    response = self.process_exception_by_middleware(e, request)
  File "/usr/local/lib/python3.6/site-packages/django/core/handlers/base.py", line 124, in _get_response
    response = wrapped_callback(request, *callback_args, **callback_kwargs)
TypeError: home_api() missing 1 required positional argument: 'callback'
ERROR 2019-01-30 09:08:10,902 log Internal Server Error: /api/home/api/
Traceback (most recent call last):
  File "/usr/local/lib/python3.6/site-packages/django/core/handlers/exception.py", line 34, in inner
    response = get_response(request)
  File "/usr/local/lib/python3.6/site-packages/django/core/handlers/base.py", line 126, in _get_response
    response = self.process_exception_by_middleware(e, request)
  File "/usr/local/lib/python3.6/site-packages/django/core/handlers/base.py", line 124, in _get_response
    response = wrapped_callback(request, *callback_args, **callback_kwargs)
TypeError: home_api() missing 1 required positional argument: 'callback'
ERROR 2019-01-30 09:15:59,637 log Internal Server Error: /api/home/api/
Traceback (most recent call last):
  File "/usr/local/lib/python3.6/site-packages/django/core/handlers/exception.py", line 34, in inner
    response = get_response(request)
  File "/usr/local/lib/python3.6/site-packages/django/core/handlers/base.py", line 126, in _get_response
    response = self.process_exception_by_middleware(e, request)
  File "/usr/local/lib/python3.6/site-packages/django/core/handlers/base.py", line 124, in _get_response
    response = wrapped_callback(request, *callback_args, **callback_kwargs)
TypeError: home_api() missing 1 required positional argument: 'callback'
ERROR 2019-01-30 09:16:22,753 log Internal Server Error: /api/home/api/
Traceback (most recent call last):
  File "/usr/local/lib/python3.6/site-packages/django/core/handlers/exception.py", line 34, in inner
    response = get_response(request)
  File "/usr/local/lib/python3.6/site-packages/django/core/handlers/base.py", line 126, in _get_response
    response = self.process_exception_by_middleware(e, request)
  File "/usr/local/lib/python3.6/site-packages/django/core/handlers/base.py", line 124, in _get_response
    response = wrapped_callback(request, *callback_args, **callback_kwargs)
TypeError: home_api() missing 1 required positional argument: 'callback'
ERROR 2019-01-30 09:16:50,028 log Internal Server Error: /api/home/api/
Traceback (most recent call last):
  File "/usr/local/lib/python3.6/site-packages/django/core/handlers/exception.py", line 34, in inner
    response = get_response(request)
  File "/usr/local/lib/python3.6/site-packages/django/core/handlers/base.py", line 126, in _get_response
    response = self.process_exception_by_middleware(e, request)
  File "/usr/local/lib/python3.6/site-packages/django/core/handlers/base.py", line 124, in _get_response
    response = wrapped_callback(request, *callback_args, **callback_kwargs)
  File "/Users/zhang/Documents/Python/PESCM/ticket/ticket_view/account.py", line 76, in home_api
    return JsonResponse({"actions_tickets": jsonData})
NameError: name 'callback' is not defined
ERROR 2019-01-30 09:16:53,969 log Internal Server Error: /api/home/api/
Traceback (most recent call last):
  File "/usr/local/lib/python3.6/site-packages/django/core/handlers/exception.py", line 34, in inner
    response = get_response(request)
  File "/usr/local/lib/python3.6/site-packages/django/core/handlers/base.py", line 126, in _get_response
    response = self.process_exception_by_middleware(e, request)
  File "/usr/local/lib/python3.6/site-packages/django/core/handlers/base.py", line 124, in _get_response
    response = wrapped_callback(request, *callback_args, **callback_kwargs)
  File "/Users/zhang/Documents/Python/PESCM/ticket/ticket_view/account.py", line 76, in home_api
    return JsonResponse({"actions_tickets": jsonData})
NameError: name 'callback' is not defined
ERROR 2019-01-30 09:17:11,584 log Internal Server Error: /api/home/api/
Traceback (most recent call last):
  File "/usr/local/lib/python3.6/site-packages/django/core/handlers/exception.py", line 34, in inner
    response = get_response(request)
  File "/usr/local/lib/python3.6/site-packages/django/core/handlers/base.py", line 126, in _get_response
    response = self.process_exception_by_middleware(e, request)
  File "/usr/local/lib/python3.6/site-packages/django/core/handlers/base.py", line 124, in _get_response
    response = wrapped_callback(request, *callback_args, **callback_kwargs)
  File "/Users/zhang/Documents/Python/PESCM/ticket/ticket_view/account.py", line 76, in home_api
    return JsonResponse({"actions_tickets": jsonData})
NameError: name 'callback' is not defined
ERROR 2019-01-30 09:17:50,508 log Internal Server Error: /api/home/api/
Traceback (most recent call last):
  File "/usr/local/lib/python3.6/site-packages/django/core/handlers/exception.py", line 34, in inner
    response = get_response(request)
  File "/usr/local/lib/python3.6/site-packages/django/core/handlers/base.py", line 126, in _get_response
    response = self.process_exception_by_middleware(e, request)
  File "/usr/local/lib/python3.6/site-packages/django/core/handlers/base.py", line 124, in _get_response
    response = wrapped_callback(request, *callback_args, **callback_kwargs)
  File "/Users/zhang/Documents/Python/PESCM/ticket/ticket_view/account.py", line 76, in home_api
    return JsonResponse({"actions_tickets": jsonData})
NameError: name 'callback' is not defined
WARNING 2019-01-30 09:47:11,603 log Not Found: /jq-paginator.js
WARNING 2019-01-30 09:47:13,062 log Not Found: /jq-paginator.js
ERROR 2019-01-30 10:35:36,320 log Internal Server Error: /api/ticket/server/detail/
Traceback (most recent call last):
  File "/usr/local/lib/python3.6/site-packages/django/core/handlers/exception.py", line 34, in inner
    response = get_response(request)
  File "/usr/local/lib/python3.6/site-packages/django/core/handlers/base.py", line 126, in _get_response
    response = self.process_exception_by_middleware(e, request)
  File "/usr/local/lib/python3.6/site-packages/django/core/handlers/base.py", line 124, in _get_response
    response = wrapped_callback(request, *callback_args, **callback_kwargs)
  File "/usr/local/lib/python3.6/site-packages/django/views/generic/base.py", line 68, in view
    return self.dispatch(request, *args, **kwargs)
  File "/usr/local/lib/python3.6/site-packages/django/views/generic/base.py", line 88, in dispatch
    return handler(request, *args, **kwargs)
  File "/Users/zhang/Documents/Python/PESCM/ticket/ticket_view/ticket.py", line 325, in get
    ticket = Ticket.objects.get(ticket_id=request.GET.get('ticket_id'))
  File "/usr/local/lib/python3.6/site-packages/django/db/models/manager.py", line 82, in manager_method
    return getattr(self.get_queryset(), name)(*args, **kwargs)
  File "/usr/local/lib/python3.6/site-packages/django/db/models/query.py", line 390, in get
    clone = self.filter(*args, **kwargs)
  File "/usr/local/lib/python3.6/site-packages/django/db/models/query.py", line 844, in filter
    return self._filter_or_exclude(False, *args, **kwargs)
  File "/usr/local/lib/python3.6/site-packages/django/db/models/query.py", line 862, in _filter_or_exclude
    clone.query.add_q(Q(*args, **kwargs))
  File "/usr/local/lib/python3.6/site-packages/django/db/models/sql/query.py", line 1263, in add_q
    clause, _ = self._add_q(q_object, self.used_aliases)
  File "/usr/local/lib/python3.6/site-packages/django/db/models/sql/query.py", line 1287, in _add_q
    split_subq=split_subq,
  File "/usr/local/lib/python3.6/site-packages/django/db/models/sql/query.py", line 1225, in build_filter
    condition = self.build_lookup(lookups, col, value)
  File "/usr/local/lib/python3.6/site-packages/django/db/models/sql/query.py", line 1096, in build_lookup
    lookup = lookup_class(lhs, rhs)
  File "/usr/local/lib/python3.6/site-packages/django/db/models/lookups.py", line 20, in __init__
    self.rhs = self.get_prep_lookup()
  File "/usr/local/lib/python3.6/site-packages/django/db/models/lookups.py", line 70, in get_prep_lookup
    return self.lhs.output_field.get_prep_value(self.rhs)
  File "/usr/local/lib/python3.6/site-packages/django/db/models/fields/__init__.py", line 965, in get_prep_value
    return int(value)
ValueError: invalid literal for int() with base 10: ''
ERROR 2019-01-30 10:36:15,559 log Internal Server Error: /api/ticket/server/detail/
Traceback (most recent call last):
  File "/usr/local/lib/python3.6/site-packages/django/core/handlers/exception.py", line 34, in inner
    response = get_response(request)
  File "/usr/local/lib/python3.6/site-packages/django/core/handlers/base.py", line 126, in _get_response
    response = self.process_exception_by_middleware(e, request)
  File "/usr/local/lib/python3.6/site-packages/django/core/handlers/base.py", line 124, in _get_response
    response = wrapped_callback(request, *callback_args, **callback_kwargs)
  File "/usr/local/lib/python3.6/site-packages/django/views/generic/base.py", line 68, in view
    return self.dispatch(request, *args, **kwargs)
  File "/usr/local/lib/python3.6/site-packages/django/views/generic/base.py", line 88, in dispatch
    return handler(request, *args, **kwargs)
  File "/Users/zhang/Documents/Python/PESCM/ticket/ticket_view/ticket.py", line 325, in get
    ticket = Ticket.objects.get(ticket_id=request.GET.get('ticket_id'))
  File "/usr/local/lib/python3.6/site-packages/django/db/models/manager.py", line 82, in manager_method
    return getattr(self.get_queryset(), name)(*args, **kwargs)
  File "/usr/local/lib/python3.6/site-packages/django/db/models/query.py", line 390, in get
    clone = self.filter(*args, **kwargs)
  File "/usr/local/lib/python3.6/site-packages/django/db/models/query.py", line 844, in filter
    return self._filter_or_exclude(False, *args, **kwargs)
  File "/usr/local/lib/python3.6/site-packages/django/db/models/query.py", line 862, in _filter_or_exclude
    clone.query.add_q(Q(*args, **kwargs))
  File "/usr/local/lib/python3.6/site-packages/django/db/models/sql/query.py", line 1263, in add_q
    clause, _ = self._add_q(q_object, self.used_aliases)
  File "/usr/local/lib/python3.6/site-packages/django/db/models/sql/query.py", line 1287, in _add_q
    split_subq=split_subq,
  File "/usr/local/lib/python3.6/site-packages/django/db/models/sql/query.py", line 1225, in build_filter
    condition = self.build_lookup(lookups, col, value)
  File "/usr/local/lib/python3.6/site-packages/django/db/models/sql/query.py", line 1096, in build_lookup
    lookup = lookup_class(lhs, rhs)
  File "/usr/local/lib/python3.6/site-packages/django/db/models/lookups.py", line 20, in __init__
    self.rhs = self.get_prep_lookup()
  File "/usr/local/lib/python3.6/site-packages/django/db/models/lookups.py", line 70, in get_prep_lookup
    return self.lhs.output_field.get_prep_value(self.rhs)
  File "/usr/local/lib/python3.6/site-packages/django/db/models/fields/__init__.py", line 965, in get_prep_value
    return int(value)
ValueError: invalid literal for int() with base 10: ''
ERROR 2019-01-30 10:37:07,256 log Internal Server Error: /api/ticket/server/detail/
Traceback (most recent call last):
  File "/usr/local/lib/python3.6/site-packages/django/core/handlers/exception.py", line 34, in inner
    response = get_response(request)
  File "/usr/local/lib/python3.6/site-packages/django/core/handlers/base.py", line 126, in _get_response
    response = self.process_exception_by_middleware(e, request)
  File "/usr/local/lib/python3.6/site-packages/django/core/handlers/base.py", line 124, in _get_response
    response = wrapped_callback(request, *callback_args, **callback_kwargs)
  File "/usr/local/lib/python3.6/site-packages/django/views/generic/base.py", line 68, in view
    return self.dispatch(request, *args, **kwargs)
  File "/usr/local/lib/python3.6/site-packages/django/views/generic/base.py", line 88, in dispatch
    return handler(request, *args, **kwargs)
  File "/Users/zhang/Documents/Python/PESCM/ticket/ticket_view/ticket.py", line 325, in get
    ticket = Ticket.objects.get(ticket_id=request.GET.get('ticket_id'))
  File "/usr/local/lib/python3.6/site-packages/django/db/models/manager.py", line 82, in manager_method
    return getattr(self.get_queryset(), name)(*args, **kwargs)
  File "/usr/local/lib/python3.6/site-packages/django/db/models/query.py", line 390, in get
    clone = self.filter(*args, **kwargs)
  File "/usr/local/lib/python3.6/site-packages/django/db/models/query.py", line 844, in filter
    return self._filter_or_exclude(False, *args, **kwargs)
  File "/usr/local/lib/python3.6/site-packages/django/db/models/query.py", line 862, in _filter_or_exclude
    clone.query.add_q(Q(*args, **kwargs))
  File "/usr/local/lib/python3.6/site-packages/django/db/models/sql/query.py", line 1263, in add_q
    clause, _ = self._add_q(q_object, self.used_aliases)
  File "/usr/local/lib/python3.6/site-packages/django/db/models/sql/query.py", line 1287, in _add_q
    split_subq=split_subq,
  File "/usr/local/lib/python3.6/site-packages/django/db/models/sql/query.py", line 1225, in build_filter
    condition = self.build_lookup(lookups, col, value)
  File "/usr/local/lib/python3.6/site-packages/django/db/models/sql/query.py", line 1096, in build_lookup
    lookup = lookup_class(lhs, rhs)
  File "/usr/local/lib/python3.6/site-packages/django/db/models/lookups.py", line 20, in __init__
    self.rhs = self.get_prep_lookup()
  File "/usr/local/lib/python3.6/site-packages/django/db/models/lookups.py", line 70, in get_prep_lookup
    return self.lhs.output_field.get_prep_value(self.rhs)
  File "/usr/local/lib/python3.6/site-packages/django/db/models/fields/__init__.py", line 965, in get_prep_value
    return int(value)
ValueError: invalid literal for int() with base 10: ''
WARNING 2019-02-01 10:38:05,856 log Not Found: /uploads/image/default.png
WARNING 2019-02-19 12:02:37,278 log Not Found: /favicon.ico
WARNING 2019-02-19 15:41:27,792 log Not Found: /uploads/image/default.png
WARNING 2019-02-19 15:43:12,853 log Not Found: /uploads/image/default.png
WARNING 2019-02-19 15:46:12,047 log Not Found: /uploads/image/default.png
WARNING 2019-02-28 10:10:10,480 log Not Found: /uploads/image/default.png
WARNING 2019-02-28 10:11:39,137 log Not Found: /favicon.ico
WARNING 2019-02-28 10:11:46,780 log Not Found: /favicon.ico
WARNING 2019-02-28 10:11:54,585 log Not Found: /favicon.ico
WARNING 2019-03-01 08:41:21,779 log Not Found: /favicon.ico
WARNING 2019-03-04 14:47:08,965 log Not Found: /favicon.ico
WARNING 2019-03-04 14:47:08,978 log Not Found: /favicon.ico
WARNING 2019-03-04 14:47:09,467 log Not Found: /favicon.ico
WARNING 2019-03-04 14:47:09,478 log Not Found: /favicon.ico
WARNING 2019-03-04 14:47:09,599 log Not Found: /favicon.ico
WARNING 2019-03-04 14:47:09,615 log Not Found: /favicon.ico
WARNING 2019-03-04 14:47:10,001 log Not Found: /favicon.ico
WARNING 2019-03-04 14:47:10,008 log Not Found: /favicon.ico
WARNING 2019-03-04 14:47:10,157 log Not Found: /favicon.ico
WARNING 2019-03-04 14:47:10,179 log Not Found: /favicon.ico
WARNING 2019-03-04 14:47:10,291 log Not Found: /favicon.ico
WARNING 2019-03-04 14:47:10,298 log Not Found: /favicon.ico
WARNING 2019-03-04 14:47:10,407 log Not Found: /favicon.ico
WARNING 2019-03-04 14:47:10,421 log Not Found: /favicon.ico
WARNING 2019-03-04 14:47:10,810 log Not Found: /favicon.ico
WARNING 2019-03-04 14:47:10,822 log Not Found: /favicon.ico
WARNING 2019-03-04 14:47:11,048 log Not Found: /favicon.ico
WARNING 2019-03-04 14:47:11,058 log Not Found: /favicon.ico
WARNING 2019-03-04 14:47:11,240 log Not Found: /favicon.ico
WARNING 2019-03-04 14:47:11,250 log Not Found: /favicon.ico
WARNING 2019-03-04 14:47:12,752 log Not Found: /favicon.ico
WARNING 2019-03-04 14:47:12,763 log Not Found: /favicon.ico
WARNING 2019-03-04 14:47:16,649 log Not Found: /favicon.ico
WARNING 2019-03-04 14:47:16,662 log Not Found: /favicon.ico
WARNING 2019-03-04 14:47:16,892 log Not Found: /favicon.ico
WARNING 2019-03-04 14:47:16,901 log Not Found: /favicon.ico
WARNING 2019-03-04 14:49:16,318 log Not Found: /favicon.ico
WARNING 2019-03-04 14:53:16,578 log Not Found: /api/ticket/logout/
WARNING 2019-03-04 14:53:16,649 log Not Found: /api/static/server_images/error.jpeg
WARNING 2019-03-04 14:53:20,503 log Not Found: /api/ticket/logout/
WARNING 2019-03-04 14:53:20,556 log Not Found: /api/static/server_images/error.jpeg
WARNING 2019-03-04 14:54:18,236 log Not Found: /favicon.ico
WARNING 2019-03-04 15:04:56,879 log Not Found: /uploads/image/default.png
ERROR 2019-03-04 15:06:57,746 log Internal Server Error: /api/ticket/server/detail/
Traceback (most recent call last):
  File "/usr/local/python3/lib/python3.6/site-packages/django/core/handlers/exception.py", line 34, in inner
    response = get_response(request)
  File "/usr/local/python3/lib/python3.6/site-packages/django/core/handlers/base.py", line 126, in _get_response
    response = self.process_exception_by_middleware(e, request)
  File "/usr/local/python3/lib/python3.6/site-packages/django/core/handlers/base.py", line 124, in _get_response
    response = wrapped_callback(request, *callback_args, **callback_kwargs)
  File "/usr/local/python3/lib/python3.6/site-packages/django/views/generic/base.py", line 68, in view
    return self.dispatch(request, *args, **kwargs)
  File "/usr/local/python3/lib/python3.6/site-packages/django/views/generic/base.py", line 88, in dispatch
    return handler(request, *args, **kwargs)
  File "./ticket/ticket_view/ticket.py", line 397, in post
    ticket.save()
  File "/usr/local/python3/lib/python3.6/site-packages/django/db/models/base.py", line 718, in save
    force_update=force_update, update_fields=update_fields)
  File "/usr/local/python3/lib/python3.6/site-packages/django/db/models/base.py", line 748, in save_base
    updated = self._save_table(raw, cls, force_insert, force_update, using, update_fields)
  File "/usr/local/python3/lib/python3.6/site-packages/django/db/models/base.py", line 812, in _save_table
    forced_update)
  File "/usr/local/python3/lib/python3.6/site-packages/django/db/models/base.py", line 861, in _do_update
    return filtered._update(values) > 0
  File "/usr/local/python3/lib/python3.6/site-packages/django/db/models/query.py", line 712, in _update
    return query.get_compiler(self.db).execute_sql(CURSOR)
  File "/usr/local/python3/lib/python3.6/site-packages/django/db/models/sql/compiler.py", line 1383, in execute_sql
    cursor = super().execute_sql(result_type)
  File "/usr/local/python3/lib/python3.6/site-packages/django/db/models/sql/compiler.py", line 1052, in execute_sql
    sql, params = self.as_sql()
  File "/usr/local/python3/lib/python3.6/site-packages/django/db/models/sql/compiler.py", line 1349, in as_sql
    val = field.get_db_prep_save(val, connection=self.connection)
  File "/usr/local/python3/lib/python3.6/site-packages/django/db/models/fields/__init__.py", line 790, in get_db_prep_save
    return self.get_db_prep_value(value, connection=connection, prepared=False)
  File "/usr/local/python3/lib/python3.6/site-packages/django/db/models/fields/__init__.py", line 1273, in get_db_prep_value
    value = self.get_prep_value(value)
  File "/usr/local/python3/lib/python3.6/site-packages/django/db/models/fields/__init__.py", line 1268, in get_prep_value
    return self.to_python(value)
  File "/usr/local/python3/lib/python3.6/site-packages/django/db/models/fields/__init__.py", line 1243, in to_python
    params={'value': value},
django.core.exceptions.ValidationError: ['’2019.03.05‘ 必须为合法的日期格式，请使用 YYYY-MM-DD 格式。']
WARNING 2019-03-04 15:07:11,481 log Not Found: /favicon.ico
ERROR 2019-03-04 15:08:01,485 log Internal Server Error: /api/ticket/server/detail/
Traceback (most recent call last):
  File "/usr/local/python3/lib/python3.6/site-packages/django/core/handlers/exception.py", line 34, in inner
    response = get_response(request)
  File "/usr/local/python3/lib/python3.6/site-packages/django/core/handlers/base.py", line 126, in _get_response
    response = self.process_exception_by_middleware(e, request)
  File "/usr/local/python3/lib/python3.6/site-packages/django/core/handlers/base.py", line 124, in _get_response
    response = wrapped_callback(request, *callback_args, **callback_kwargs)
  File "/usr/local/python3/lib/python3.6/site-packages/django/views/generic/base.py", line 68, in view
    return self.dispatch(request, *args, **kwargs)
  File "/usr/local/python3/lib/python3.6/site-packages/django/views/generic/base.py", line 88, in dispatch
    return handler(request, *args, **kwargs)
  File "./ticket/ticket_view/ticket.py", line 397, in post
    ticket.save()
  File "/usr/local/python3/lib/python3.6/site-packages/django/db/models/base.py", line 718, in save
    force_update=force_update, update_fields=update_fields)
  File "/usr/local/python3/lib/python3.6/site-packages/django/db/models/base.py", line 748, in save_base
    updated = self._save_table(raw, cls, force_insert, force_update, using, update_fields)
  File "/usr/local/python3/lib/python3.6/site-packages/django/db/models/base.py", line 812, in _save_table
    forced_update)
  File "/usr/local/python3/lib/python3.6/site-packages/django/db/models/base.py", line 861, in _do_update
    return filtered._update(values) > 0
  File "/usr/local/python3/lib/python3.6/site-packages/django/db/models/query.py", line 712, in _update
    return query.get_compiler(self.db).execute_sql(CURSOR)
  File "/usr/local/python3/lib/python3.6/site-packages/django/db/models/sql/compiler.py", line 1383, in execute_sql
    cursor = super().execute_sql(result_type)
  File "/usr/local/python3/lib/python3.6/site-packages/django/db/models/sql/compiler.py", line 1052, in execute_sql
    sql, params = self.as_sql()
  File "/usr/local/python3/lib/python3.6/site-packages/django/db/models/sql/compiler.py", line 1349, in as_sql
    val = field.get_db_prep_save(val, connection=self.connection)
  File "/usr/local/python3/lib/python3.6/site-packages/django/db/models/fields/__init__.py", line 790, in get_db_prep_save
    return self.get_db_prep_value(value, connection=connection, prepared=False)
  File "/usr/local/python3/lib/python3.6/site-packages/django/db/models/fields/__init__.py", line 1273, in get_db_prep_value
    value = self.get_prep_value(value)
  File "/usr/local/python3/lib/python3.6/site-packages/django/db/models/fields/__init__.py", line 1268, in get_prep_value
    return self.to_python(value)
  File "/usr/local/python3/lib/python3.6/site-packages/django/db/models/fields/__init__.py", line 1243, in to_python
    params={'value': value},
django.core.exceptions.ValidationError: ['’2019.03.05‘ 必须为合法的日期格式，请使用 YYYY-MM-DD 格式。']
ERROR 2019-03-04 15:19:08,560 log Internal Server Error: /api/ticket/server/detail/
Traceback (most recent call last):
  File "/usr/local/python3/lib/python3.6/site-packages/django/core/handlers/exception.py", line 34, in inner
    response = get_response(request)
  File "/usr/local/python3/lib/python3.6/site-packages/django/core/handlers/base.py", line 126, in _get_response
    response = self.process_exception_by_middleware(e, request)
  File "/usr/local/python3/lib/python3.6/site-packages/django/core/handlers/base.py", line 124, in _get_response
    response = wrapped_callback(request, *callback_args, **callback_kwargs)
  File "/usr/local/python3/lib/python3.6/site-packages/django/views/generic/base.py", line 68, in view
    return self.dispatch(request, *args, **kwargs)
  File "/usr/local/python3/lib/python3.6/site-packages/django/views/generic/base.py", line 88, in dispatch
    return handler(request, *args, **kwargs)
  File "./ticket/ticket_view/ticket.py", line 397, in post
    ticket.save()
  File "/usr/local/python3/lib/python3.6/site-packages/django/db/models/base.py", line 718, in save
    force_update=force_update, update_fields=update_fields)
  File "/usr/local/python3/lib/python3.6/site-packages/django/db/models/base.py", line 748, in save_base
    updated = self._save_table(raw, cls, force_insert, force_update, using, update_fields)
  File "/usr/local/python3/lib/python3.6/site-packages/django/db/models/base.py", line 812, in _save_table
    forced_update)
  File "/usr/local/python3/lib/python3.6/site-packages/django/db/models/base.py", line 861, in _do_update
    return filtered._update(values) > 0
  File "/usr/local/python3/lib/python3.6/site-packages/django/db/models/query.py", line 712, in _update
    return query.get_compiler(self.db).execute_sql(CURSOR)
  File "/usr/local/python3/lib/python3.6/site-packages/django/db/models/sql/compiler.py", line 1383, in execute_sql
    cursor = super().execute_sql(result_type)
  File "/usr/local/python3/lib/python3.6/site-packages/django/db/models/sql/compiler.py", line 1052, in execute_sql
    sql, params = self.as_sql()
  File "/usr/local/python3/lib/python3.6/site-packages/django/db/models/sql/compiler.py", line 1349, in as_sql
    val = field.get_db_prep_save(val, connection=self.connection)
  File "/usr/local/python3/lib/python3.6/site-packages/django/db/models/fields/__init__.py", line 790, in get_db_prep_save
    return self.get_db_prep_value(value, connection=connection, prepared=False)
  File "/usr/local/python3/lib/python3.6/site-packages/django/db/models/fields/__init__.py", line 1273, in get_db_prep_value
    value = self.get_prep_value(value)
  File "/usr/local/python3/lib/python3.6/site-packages/django/db/models/fields/__init__.py", line 1268, in get_prep_value
    return self.to_python(value)
  File "/usr/local/python3/lib/python3.6/site-packages/django/db/models/fields/__init__.py", line 1243, in to_python
    params={'value': value},
django.core.exceptions.ValidationError: ['’‘ 必须为合法的日期格式，请使用 YYYY-MM-DD 格式。']
ERROR 2019-03-04 15:19:53,083 log Internal Server Error: /api/ticket/server/detail/
Traceback (most recent call last):
  File "/usr/local/python3/lib/python3.6/site-packages/django/core/handlers/exception.py", line 34, in inner
    response = get_response(request)
  File "/usr/local/python3/lib/python3.6/site-packages/django/core/handlers/base.py", line 126, in _get_response
    response = self.process_exception_by_middleware(e, request)
  File "/usr/local/python3/lib/python3.6/site-packages/django/core/handlers/base.py", line 124, in _get_response
    response = wrapped_callback(request, *callback_args, **callback_kwargs)
  File "/usr/local/python3/lib/python3.6/site-packages/django/views/generic/base.py", line 68, in view
    return self.dispatch(request, *args, **kwargs)
  File "/usr/local/python3/lib/python3.6/site-packages/django/views/generic/base.py", line 88, in dispatch
    return handler(request, *args, **kwargs)
  File "./ticket/ticket_view/ticket.py", line 397, in post
    ticket.save()
  File "/usr/local/python3/lib/python3.6/site-packages/django/db/models/base.py", line 718, in save
    force_update=force_update, update_fields=update_fields)
  File "/usr/local/python3/lib/python3.6/site-packages/django/db/models/base.py", line 748, in save_base
    updated = self._save_table(raw, cls, force_insert, force_update, using, update_fields)
  File "/usr/local/python3/lib/python3.6/site-packages/django/db/models/base.py", line 812, in _save_table
    forced_update)
  File "/usr/local/python3/lib/python3.6/site-packages/django/db/models/base.py", line 861, in _do_update
    return filtered._update(values) > 0
  File "/usr/local/python3/lib/python3.6/site-packages/django/db/models/query.py", line 712, in _update
    return query.get_compiler(self.db).execute_sql(CURSOR)
  File "/usr/local/python3/lib/python3.6/site-packages/django/db/models/sql/compiler.py", line 1383, in execute_sql
    cursor = super().execute_sql(result_type)
  File "/usr/local/python3/lib/python3.6/site-packages/django/db/models/sql/compiler.py", line 1052, in execute_sql
    sql, params = self.as_sql()
  File "/usr/local/python3/lib/python3.6/site-packages/django/db/models/sql/compiler.py", line 1349, in as_sql
    val = field.get_db_prep_save(val, connection=self.connection)
  File "/usr/local/python3/lib/python3.6/site-packages/django/db/models/fields/__init__.py", line 790, in get_db_prep_save
    return self.get_db_prep_value(value, connection=connection, prepared=False)
  File "/usr/local/python3/lib/python3.6/site-packages/django/db/models/fields/__init__.py", line 1273, in get_db_prep_value
    value = self.get_prep_value(value)
  File "/usr/local/python3/lib/python3.6/site-packages/django/db/models/fields/__init__.py", line 1268, in get_prep_value
    return self.to_python(value)
  File "/usr/local/python3/lib/python3.6/site-packages/django/db/models/fields/__init__.py", line 1243, in to_python
    params={'value': value},
django.core.exceptions.ValidationError: ['’‘ 必须为合法的日期格式，请使用 YYYY-MM-DD 格式。']
ERROR 2019-03-04 15:45:24,425 log Internal Server Error: /api/ticket/server/detail/
Traceback (most recent call last):
  File "/usr/local/python3/lib/python3.6/site-packages/django/core/handlers/exception.py", line 34, in inner
    response = get_response(request)
  File "/usr/local/python3/lib/python3.6/site-packages/django/core/handlers/base.py", line 126, in _get_response
    response = self.process_exception_by_middleware(e, request)
  File "/usr/local/python3/lib/python3.6/site-packages/django/core/handlers/base.py", line 124, in _get_response
    response = wrapped_callback(request, *callback_args, **callback_kwargs)
  File "/usr/local/python3/lib/python3.6/site-packages/django/views/generic/base.py", line 68, in view
    return self.dispatch(request, *args, **kwargs)
  File "/usr/local/python3/lib/python3.6/site-packages/django/views/generic/base.py", line 88, in dispatch
    return handler(request, *args, **kwargs)
  File "./ticket/ticket_view/ticket.py", line 397, in post
    ticket.save()
  File "/usr/local/python3/lib/python3.6/site-packages/django/db/models/base.py", line 718, in save
    force_update=force_update, update_fields=update_fields)
  File "/usr/local/python3/lib/python3.6/site-packages/django/db/models/base.py", line 748, in save_base
    updated = self._save_table(raw, cls, force_insert, force_update, using, update_fields)
  File "/usr/local/python3/lib/python3.6/site-packages/django/db/models/base.py", line 812, in _save_table
    forced_update)
  File "/usr/local/python3/lib/python3.6/site-packages/django/db/models/base.py", line 861, in _do_update
    return filtered._update(values) > 0
  File "/usr/local/python3/lib/python3.6/site-packages/django/db/models/query.py", line 712, in _update
    return query.get_compiler(self.db).execute_sql(CURSOR)
  File "/usr/local/python3/lib/python3.6/site-packages/django/db/models/sql/compiler.py", line 1383, in execute_sql
    cursor = super().execute_sql(result_type)
  File "/usr/local/python3/lib/python3.6/site-packages/django/db/models/sql/compiler.py", line 1052, in execute_sql
    sql, params = self.as_sql()
  File "/usr/local/python3/lib/python3.6/site-packages/django/db/models/sql/compiler.py", line 1349, in as_sql
    val = field.get_db_prep_save(val, connection=self.connection)
  File "/usr/local/python3/lib/python3.6/site-packages/django/db/models/fields/__init__.py", line 790, in get_db_prep_save
    return self.get_db_prep_value(value, connection=connection, prepared=False)
  File "/usr/local/python3/lib/python3.6/site-packages/django/db/models/fields/__init__.py", line 1273, in get_db_prep_value
    value = self.get_prep_value(value)
  File "/usr/local/python3/lib/python3.6/site-packages/django/db/models/fields/__init__.py", line 1268, in get_prep_value
    return self.to_python(value)
  File "/usr/local/python3/lib/python3.6/site-packages/django/db/models/fields/__init__.py", line 1243, in to_python
    params={'value': value},
django.core.exceptions.ValidationError: ['’2019/03/05‘ 必须为合法的日期格式，请使用 YYYY-MM-DD 格式。']
WARNING 2019-03-04 15:49:41,680 log Not Found: /favicon.ico
WARNING 2019-03-04 15:51:38,560 log Not Found: /api/api/login/
WARNING 2019-03-04 15:53:28,349 log Not Found: /favicon.ico
ERROR 2019-03-04 15:54:08,370 log Internal Server Error: /api/ticket/server/detail/
Traceback (most recent call last):
  File "/usr/local/python3/lib/python3.6/site-packages/django/core/handlers/exception.py", line 34, in inner
    response = get_response(request)
  File "/usr/local/python3/lib/python3.6/site-packages/django/core/handlers/base.py", line 126, in _get_response
    response = self.process_exception_by_middleware(e, request)
  File "/usr/local/python3/lib/python3.6/site-packages/django/core/handlers/base.py", line 124, in _get_response
    response = wrapped_callback(request, *callback_args, **callback_kwargs)
  File "/usr/local/python3/lib/python3.6/site-packages/django/views/generic/base.py", line 68, in view
    return self.dispatch(request, *args, **kwargs)
  File "/usr/local/python3/lib/python3.6/site-packages/django/views/generic/base.py", line 88, in dispatch
    return handler(request, *args, **kwargs)
  File "./ticket/ticket_view/ticket.py", line 397, in post
    ticket.save()
  File "/usr/local/python3/lib/python3.6/site-packages/django/db/models/base.py", line 718, in save
    force_update=force_update, update_fields=update_fields)
  File "/usr/local/python3/lib/python3.6/site-packages/django/db/models/base.py", line 748, in save_base
    updated = self._save_table(raw, cls, force_insert, force_update, using, update_fields)
  File "/usr/local/python3/lib/python3.6/site-packages/django/db/models/base.py", line 812, in _save_table
    forced_update)
  File "/usr/local/python3/lib/python3.6/site-packages/django/db/models/base.py", line 861, in _do_update
    return filtered._update(values) > 0
  File "/usr/local/python3/lib/python3.6/site-packages/django/db/models/query.py", line 712, in _update
    return query.get_compiler(self.db).execute_sql(CURSOR)
  File "/usr/local/python3/lib/python3.6/site-packages/django/db/models/sql/compiler.py", line 1383, in execute_sql
    cursor = super().execute_sql(result_type)
  File "/usr/local/python3/lib/python3.6/site-packages/django/db/models/sql/compiler.py", line 1052, in execute_sql
    sql, params = self.as_sql()
  File "/usr/local/python3/lib/python3.6/site-packages/django/db/models/sql/compiler.py", line 1349, in as_sql
    val = field.get_db_prep_save(val, connection=self.connection)
  File "/usr/local/python3/lib/python3.6/site-packages/django/db/models/fields/__init__.py", line 790, in get_db_prep_save
    return self.get_db_prep_value(value, connection=connection, prepared=False)
  File "/usr/local/python3/lib/python3.6/site-packages/django/db/models/fields/__init__.py", line 1273, in get_db_prep_value
    value = self.get_prep_value(value)
  File "/usr/local/python3/lib/python3.6/site-packages/django/db/models/fields/__init__.py", line 1268, in get_prep_value
    return self.to_python(value)
  File "/usr/local/python3/lib/python3.6/site-packages/django/db/models/fields/__init__.py", line 1243, in to_python
    params={'value': value},
django.core.exceptions.ValidationError: ['’‘ 必须为合法的日期格式，请使用 YYYY-MM-DD 格式。']
ERROR 2019-03-04 15:54:34,485 log Internal Server Error: /api/ticket/server/detail/
Traceback (most recent call last):
  File "/usr/local/python3/lib/python3.6/site-packages/django/core/handlers/exception.py", line 34, in inner
    response = get_response(request)
  File "/usr/local/python3/lib/python3.6/site-packages/django/core/handlers/base.py", line 126, in _get_response
    response = self.process_exception_by_middleware(e, request)
  File "/usr/local/python3/lib/python3.6/site-packages/django/core/handlers/base.py", line 124, in _get_response
    response = wrapped_callback(request, *callback_args, **callback_kwargs)
  File "/usr/local/python3/lib/python3.6/site-packages/django/views/generic/base.py", line 68, in view
    return self.dispatch(request, *args, **kwargs)
  File "/usr/local/python3/lib/python3.6/site-packages/django/views/generic/base.py", line 88, in dispatch
    return handler(request, *args, **kwargs)
  File "./ticket/ticket_view/ticket.py", line 397, in post
    ticket.save()
  File "/usr/local/python3/lib/python3.6/site-packages/django/db/models/base.py", line 718, in save
    force_update=force_update, update_fields=update_fields)
  File "/usr/local/python3/lib/python3.6/site-packages/django/db/models/base.py", line 748, in save_base
    updated = self._save_table(raw, cls, force_insert, force_update, using, update_fields)
  File "/usr/local/python3/lib/python3.6/site-packages/django/db/models/base.py", line 812, in _save_table
    forced_update)
  File "/usr/local/python3/lib/python3.6/site-packages/django/db/models/base.py", line 861, in _do_update
    return filtered._update(values) > 0
  File "/usr/local/python3/lib/python3.6/site-packages/django/db/models/query.py", line 712, in _update
    return query.get_compiler(self.db).execute_sql(CURSOR)
  File "/usr/local/python3/lib/python3.6/site-packages/django/db/models/sql/compiler.py", line 1383, in execute_sql
    cursor = super().execute_sql(result_type)
  File "/usr/local/python3/lib/python3.6/site-packages/django/db/models/sql/compiler.py", line 1052, in execute_sql
    sql, params = self.as_sql()
  File "/usr/local/python3/lib/python3.6/site-packages/django/db/models/sql/compiler.py", line 1349, in as_sql
    val = field.get_db_prep_save(val, connection=self.connection)
  File "/usr/local/python3/lib/python3.6/site-packages/django/db/models/fields/__init__.py", line 790, in get_db_prep_save
    return self.get_db_prep_value(value, connection=connection, prepared=False)
  File "/usr/local/python3/lib/python3.6/site-packages/django/db/models/fields/__init__.py", line 1273, in get_db_prep_value
    value = self.get_prep_value(value)
  File "/usr/local/python3/lib/python3.6/site-packages/django/db/models/fields/__init__.py", line 1268, in get_prep_value
    return self.to_python(value)
  File "/usr/local/python3/lib/python3.6/site-packages/django/db/models/fields/__init__.py", line 1243, in to_python
    params={'value': value},
django.core.exceptions.ValidationError: ['’‘ 必须为合法的日期格式，请使用 YYYY-MM-DD 格式。']
WARNING 2019-03-04 16:37:17,858 log Not Found: /uploads/image/default.png
WARNING 2019-03-04 16:37:34,833 log Not Found: /favicon.ico
WARNING 2019-03-04 16:37:37,769 log Not Found: /favicon.ico
WARNING 2019-03-04 16:37:47,224 log Not Found: /uploads/image/default.png
WARNING 2019-03-04 16:37:48,687 log Not Found: /favicon.ico
WARNING 2019-03-04 16:38:54,960 log Not Found: /uploads/image/default.png
WARNING 2019-03-04 16:39:09,475 log Not Found: /uploads/image/default.png
ERROR 2019-03-04 16:39:22,438 log Internal Server Error: /api/ticket/detail/
Traceback (most recent call last):
  File "/usr/local/python3/lib/python3.6/site-packages/django/core/handlers/exception.py", line 34, in inner
    response = get_response(request)
  File "/usr/local/python3/lib/python3.6/site-packages/django/core/handlers/base.py", line 126, in _get_response
    response = self.process_exception_by_middleware(e, request)
  File "/usr/local/python3/lib/python3.6/site-packages/django/core/handlers/base.py", line 124, in _get_response
    response = wrapped_callback(request, *callback_args, **callback_kwargs)
  File "/usr/local/python3/lib/python3.6/site-packages/django/views/generic/base.py", line 68, in view
    return self.dispatch(request, *args, **kwargs)
  File "/usr/local/python3/lib/python3.6/site-packages/django/views/generic/base.py", line 88, in dispatch
    return handler(request, *args, **kwargs)
  File "./ticket/ticket_view/ticket.py", line 269, in get
    ticket = Ticket.objects.get(ticket_show_id=request.GET.get('ticket_id'))
  File "/usr/local/python3/lib/python3.6/site-packages/django/db/models/manager.py", line 82, in manager_method
    return getattr(self.get_queryset(), name)(*args, **kwargs)
  File "/usr/local/python3/lib/python3.6/site-packages/django/db/models/query.py", line 403, in get
    (self.model._meta.object_name, num)
ticket.ticke_model.ticket.Ticket.MultipleObjectsReturned: get() returned more than one Ticket -- it returned 8!
WARNING 2019-03-04 16:42:13,694 log Not Found: /uploads/image/default.png
